INFO 2025-05-15 21:26:58,996 autoreload 40548 20628 Watching for file changes with StatReloader
INFO 2025-05-15 21:33:19,051 autoreload 40548 20628 A:\web django\GradProject\New folder\BookNest\BookNest\recommendation\utils.py changed, reloading.
INFO 2025-05-15 21:33:22,237 autoreload 25192 24936 Watching for file changes with StatReloader
INFO 2025-05-15 21:33:28,836 autoreload 25192 24936 A:\web django\GradProject\New folder\BookNest\BookNest\recommendation\utils.py changed, reloading.
INFO 2025-05-15 21:33:31,798 autoreload 14272 19772 Watching for file changes with StatReloader
INFO 2025-05-15 21:41:09,589 autoreload 14272 19772 A:\web django\GradProject\New folder\BookNest\BookNest\recommendation\recommendation_engine.py changed, reloading.
INFO 2025-05-15 21:41:12,829 autoreload 31332 14804 Watching for file changes with StatReloader
INFO 2025-05-16 18:47:53,720 autoreload 36740 10792 Watching for file changes with StatReloader
INFO 2025-05-16 18:48:03,042 basehttp 36740 30716 "POST /api/v1/users/login/ HTTP/1.1" 200 675
WARNING 2025-05-16 18:48:13,859 log 36740 30716 Not Found: /api/v1/recommendation/api/recommendations/user-recommendations/generate/
WARNING 2025-05-16 18:48:13,860 basehttp 36740 30716 "POST /api/v1/recommendation/api/recommendations/user-recommendations/generate/ HTTP/1.1" 404 11224
WARNING 2025-05-16 18:49:10,379 log 36740 30716 Not Found: /api/v1/recommendation/recommendations/user-recommendations/generate/
WARNING 2025-05-16 18:49:10,382 basehttp 36740 30716 "POST /api/v1/recommendation/recommendations/user-recommendations/generate/ HTTP/1.1" 404 11212
INFO 2025-05-16 18:49:14,929 basehttp 36740 30716 "POST /api/v1/recommendation/user-recommendations/generate/ HTTP/1.1" 200 1799
WARNING 2025-05-16 18:49:41,817 log 36740 30716 Unauthorized: /api/v1/recommendation/user-recommendations/generate/
WARNING 2025-05-16 18:49:41,823 basehttp 36740 30716 "POST /api/v1/recommendation/user-recommendations/generate/ HTTP/1.1" 401 58
INFO 2025-05-16 18:50:10,095 basehttp 36740 30716 "POST /api/v1/recommendation/user-recommendations/generate/ HTTP/1.1" 200 1808
INFO 2025-05-16 18:51:05,279 basehttp 36740 30716 "POST /api/v1/recommendation/user-recommendations/generate/ HTTP/1.1" 200 1808
INFO 2025-05-16 18:58:55,331 basehttp 36740 39356 "GET /api/v1/recommendation/user-recommendations/ HTTP/1.1" 200 1808
INFO 2025-05-16 18:58:59,448 basehttp 36740 39356 "GET /api/v1/recommendation/user-recommendations/ HTTP/1.1" 200 1808
INFO 2025-05-16 19:22:54,328 autoreload 36740 10792 A:\web django\GradProject\New folder\BookNest\BookNest\recommendation\urls.py changed, reloading.
INFO 2025-05-16 19:23:00,795 autoreload 13940 23564 Watching for file changes with StatReloader
INFO 2025-05-16 19:23:24,472 autoreload 13940 23564 A:\web django\GradProject\New folder\BookNest\BookNest\recommendation\urls.py changed, reloading.
INFO 2025-05-16 19:23:28,575 autoreload 14048 22056 Watching for file changes with StatReloader
INFO 2025-05-16 19:23:39,464 autoreload 14048 22056 A:\web django\GradProject\New folder\BookNest\BookNest\recommendation\urls.py changed, reloading.
INFO 2025-05-16 19:23:43,106 autoreload 41832 6552 Watching for file changes with StatReloader
WARNING 2025-05-16 19:24:11,727 log 41832 23284 Not Found: /api/v1/register/
WARNING 2025-05-16 19:24:11,730 basehttp 41832 23284 "POST /api/v1/register/ HTTP/1.1" 404 3691
INFO 2025-05-16 19:24:24,576 basehttp 41832 23284 "POST /api/v1/users/register/ HTTP/1.1" 201 679
ERROR 2025-05-16 19:24:44,759 log 41832 16744 Internal Server Error: /api/v1/books/rating/create/
Traceback (most recent call last):
  File "C:\Users\ahmed\AppData\Local\Programs\Python\Python312\Lib\site-packages\urllib3\connection.py", line 174, in _new_conn
    conn = connection.create_connection(
           ^^^^^^^^^^^^^^^^^^^^^^^^^^^^^
  File "C:\Users\ahmed\AppData\Local\Programs\Python\Python312\Lib\site-packages\urllib3\util\connection.py", line 95, in create_connection
    raise err
  File "C:\Users\ahmed\AppData\Local\Programs\Python\Python312\Lib\site-packages\urllib3\util\connection.py", line 85, in create_connection
    sock.connect(sa)
ConnectionRefusedError: [WinError 10061] No connection could be made because the target machine actively refused it

During handling of the above exception, another exception occurred:

Traceback (most recent call last):
  File "C:\Users\ahmed\AppData\Local\Programs\Python\Python312\Lib\site-packages\elasticsearch\connection\http_urllib3.py", line 255, in perform_request
    response = self.pool.urlopen(
               ^^^^^^^^^^^^^^^^^^
  File "C:\Users\ahmed\AppData\Local\Programs\Python\Python312\Lib\site-packages\urllib3\connectionpool.py", line 802, in urlopen
    retries = retries.increment(
              ^^^^^^^^^^^^^^^^^^
  File "C:\Users\ahmed\AppData\Local\Programs\Python\Python312\Lib\site-packages\urllib3\util\retry.py", line 527, in increment
    raise six.reraise(type(error), error, _stacktrace)
          ^^^^^^^^^^^^^^^^^^^^^^^^^^^^^^^^^^^^^^^^^^^^
  File "C:\Users\ahmed\AppData\Local\Programs\Python\Python312\Lib\site-packages\urllib3\packages\six.py", line 770, in reraise
    raise value
  File "C:\Users\ahmed\AppData\Local\Programs\Python\Python312\Lib\site-packages\urllib3\connectionpool.py", line 716, in urlopen
    httplib_response = self._make_request(
                       ^^^^^^^^^^^^^^^^^^^
  File "C:\Users\ahmed\AppData\Local\Programs\Python\Python312\Lib\site-packages\urllib3\connectionpool.py", line 416, in _make_request
    conn.request(method, url, **httplib_request_kw)
  File "C:\Users\ahmed\AppData\Local\Programs\Python\Python312\Lib\site-packages\urllib3\connection.py", line 244, in request
    super(HTTPConnection, self).request(method, url, body=body, headers=headers)
  File "C:\Users\ahmed\AppData\Local\Programs\Python\Python312\Lib\http\client.py", line 1319, in request
    self._send_request(method, url, body, headers, encode_chunked)
  File "C:\Users\ahmed\AppData\Local\Programs\Python\Python312\Lib\http\client.py", line 1365, in _send_request
    self.endheaders(body, encode_chunked=encode_chunked)
  File "C:\Users\ahmed\AppData\Local\Programs\Python\Python312\Lib\http\client.py", line 1314, in endheaders
    self._send_output(message_body, encode_chunked=encode_chunked)
  File "C:\Users\ahmed\AppData\Local\Programs\Python\Python312\Lib\http\client.py", line 1074, in _send_output
    self.send(msg)
  File "C:\Users\ahmed\AppData\Local\Programs\Python\Python312\Lib\http\client.py", line 1018, in send
    self.connect()
  File "C:\Users\ahmed\AppData\Local\Programs\Python\Python312\Lib\site-packages\urllib3\connection.py", line 205, in connect
    conn = self._new_conn()
           ^^^^^^^^^^^^^^^^
  File "C:\Users\ahmed\AppData\Local\Programs\Python\Python312\Lib\site-packages\urllib3\connection.py", line 186, in _new_conn
    raise NewConnectionError(
urllib3.exceptions.NewConnectionError: <urllib3.connection.HTTPConnection object at 0x0000020B4A808FB0>: Failed to establish a new connection: [WinError 10061] No connection could be made because the target machine actively refused it

During handling of the above exception, another exception occurred:

Traceback (most recent call last):
  File "C:\Users\ahmed\AppData\Local\Programs\Python\Python312\Lib\site-packages\django\core\handlers\exception.py", line 55, in inner
    response = get_response(request)
               ^^^^^^^^^^^^^^^^^^^^^
  File "C:\Users\ahmed\AppData\Local\Programs\Python\Python312\Lib\site-packages\django\core\handlers\base.py", line 197, in _get_response
    response = wrapped_callback(request, *callback_args, **callback_kwargs)
               ^^^^^^^^^^^^^^^^^^^^^^^^^^^^^^^^^^^^^^^^^^^^^^^^^^^^^^^^^^^^
  File "C:\Users\ahmed\AppData\Local\Programs\Python\Python312\Lib\site-packages\django\views\decorators\csrf.py", line 65, in _view_wrapper
    return view_func(request, *args, **kwargs)
           ^^^^^^^^^^^^^^^^^^^^^^^^^^^^^^^^^^^
  File "C:\Users\ahmed\AppData\Local\Programs\Python\Python312\Lib\site-packages\django\views\generic\base.py", line 104, in view
    return self.dispatch(request, *args, **kwargs)
           ^^^^^^^^^^^^^^^^^^^^^^^^^^^^^^^^^^^^^^^
  File "C:\Users\ahmed\AppData\Local\Programs\Python\Python312\Lib\site-packages\rest_framework\views.py", line 509, in dispatch
    response = self.handle_exception(exc)
               ^^^^^^^^^^^^^^^^^^^^^^^^^^
  File "C:\Users\ahmed\AppData\Local\Programs\Python\Python312\Lib\site-packages\rest_framework\views.py", line 469, in handle_exception
    self.raise_uncaught_exception(exc)
  File "C:\Users\ahmed\AppData\Local\Programs\Python\Python312\Lib\site-packages\rest_framework\views.py", line 480, in raise_uncaught_exception
    raise exc
  File "C:\Users\ahmed\AppData\Local\Programs\Python\Python312\Lib\site-packages\rest_framework\views.py", line 506, in dispatch
    response = handler(request, *args, **kwargs)
               ^^^^^^^^^^^^^^^^^^^^^^^^^^^^^^^^^
  File "C:\Users\ahmed\AppData\Local\Programs\Python\Python312\Lib\site-packages\rest_framework\generics.py", line 194, in post
    return self.create(request, *args, **kwargs)
           ^^^^^^^^^^^^^^^^^^^^^^^^^^^^^^^^^^^^^
  File "C:\Users\ahmed\AppData\Local\Programs\Python\Python312\Lib\site-packages\rest_framework\mixins.py", line 19, in create
    self.perform_create(serializer)
  File "A:\web django\GradProject\New folder\BookNest\BookNest\books\views\review_views.py", line 156, in perform_create
    serializer.save(user=self.request.user, book=book)
  File "C:\Users\ahmed\AppData\Local\Programs\Python\Python312\Lib\site-packages\rest_framework\serializers.py", line 208, in save
    self.instance = self.create(validated_data)
                    ^^^^^^^^^^^^^^^^^^^^^^^^^^^
  File "A:\web django\GradProject\New folder\BookNest\BookNest\books\serializers\review_serializers.py", line 83, in create
    book.save()
  File "C:\Users\ahmed\AppData\Local\Programs\Python\Python312\Lib\site-packages\django\db\models\base.py", line 891, in save
    self.save_base(
  File "C:\Users\ahmed\AppData\Local\Programs\Python\Python312\Lib\site-packages\django\db\models\base.py", line 1012, in save_base
    post_save.send(
  File "C:\Users\ahmed\AppData\Local\Programs\Python\Python312\Lib\site-packages\django\dispatch\dispatcher.py", line 189, in send
    response = receiver(signal=self, sender=sender, **named)
               ^^^^^^^^^^^^^^^^^^^^^^^^^^^^^^^^^^^^^^^^^^^^^
  File "C:\Users\ahmed\AppData\Local\Programs\Python\Python312\Lib\site-packages\django_elasticsearch_dsl\signals.py", line 61, in handle_save
    registry.update(instance)
  File "C:\Users\ahmed\AppData\Local\Programs\Python\Python312\Lib\site-packages\django_elasticsearch_dsl\registries.py", line 141, in update
    doc().update(instance, **kwargs)
  File "C:\Users\ahmed\AppData\Local\Programs\Python\Python312\Lib\site-packages\django_elasticsearch_dsl\documents.py", line 259, in update
    return self._bulk(
           ^^^^^^^^^^^
  File "C:\Users\ahmed\AppData\Local\Programs\Python\Python312\Lib\site-packages\django_elasticsearch_dsl\documents.py", line 236, in _bulk
    return self.bulk(*args, **kwargs)
           ^^^^^^^^^^^^^^^^^^^^^^^^^^
  File "C:\Users\ahmed\AppData\Local\Programs\Python\Python312\Lib\site-packages\django_elasticsearch_dsl\documents.py", line 178, in bulk
    response = bulk(client=self._get_connection(), actions=actions, **kwargs)
               ^^^^^^^^^^^^^^^^^^^^^^^^^^^^^^^^^^^^^^^^^^^^^^^^^^^^^^^^^^^^^^
  File "C:\Users\ahmed\AppData\Local\Programs\Python\Python312\Lib\site-packages\elasticsearch\helpers\actions.py", line 410, in bulk
    for ok, item in streaming_bulk(
  File "C:\Users\ahmed\AppData\Local\Programs\Python\Python312\Lib\site-packages\elasticsearch\helpers\actions.py", line 329, in streaming_bulk
    for data, (ok, info) in zip(
  File "C:\Users\ahmed\AppData\Local\Programs\Python\Python312\Lib\site-packages\elasticsearch\helpers\actions.py", line 256, in _process_bulk_chunk
    for item in gen:
  File "C:\Users\ahmed\AppData\Local\Programs\Python\Python312\Lib\site-packages\elasticsearch\helpers\actions.py", line 195, in _process_bulk_chunk_error
    raise error
  File "C:\Users\ahmed\AppData\Local\Programs\Python\Python312\Lib\site-packages\elasticsearch\helpers\actions.py", line 240, in _process_bulk_chunk
    resp = client.bulk(*args, body="\n".join(bulk_actions) + "\n", **kwargs)
           ^^^^^^^^^^^^^^^^^^^^^^^^^^^^^^^^^^^^^^^^^^^^^^^^^^^^^^^^^^^^^^^^^
  File "C:\Users\ahmed\AppData\Local\Programs\Python\Python312\Lib\site-packages\elasticsearch\client\utils.py", line 347, in _wrapped
    return func(*args, params=params, headers=headers, **kwargs)
           ^^^^^^^^^^^^^^^^^^^^^^^^^^^^^^^^^^^^^^^^^^^^^^^^^^^^^
  File "C:\Users\ahmed\AppData\Local\Programs\Python\Python312\Lib\site-packages\elasticsearch\client\__init__.py", line 472, in bulk
    return self.transport.perform_request(
           ^^^^^^^^^^^^^^^^^^^^^^^^^^^^^^^
  File "C:\Users\ahmed\AppData\Local\Programs\Python\Python312\Lib\site-packages\elasticsearch\transport.py", line 417, in perform_request
    self._do_verify_elasticsearch(headers=headers, timeout=timeout)
  File "C:\Users\ahmed\AppData\Local\Programs\Python\Python312\Lib\site-packages\elasticsearch\transport.py", line 606, in _do_verify_elasticsearch
    raise error
  File "C:\Users\ahmed\AppData\Local\Programs\Python\Python312\Lib\site-packages\elasticsearch\transport.py", line 569, in _do_verify_elasticsearch
    _, info_headers, info_response = conn.perform_request(
                                     ^^^^^^^^^^^^^^^^^^^^^
  File "C:\Users\ahmed\AppData\Local\Programs\Python\Python312\Lib\site-packages\elasticsearch\connection\http_urllib3.py", line 280, in perform_request
    raise ConnectionError("N/A", str(e), e)
elasticsearch.exceptions.ConnectionError: ConnectionError(<urllib3.connection.HTTPConnection object at 0x0000020B4A808FB0>: Failed to establish a new connection: [WinError 10061] No connection could be made because the target machine actively refused it) caused by: NewConnectionError(<urllib3.connection.HTTPConnection object at 0x0000020B4A808FB0>: Failed to establish a new connection: [WinError 10061] No connection could be made because the target machine actively refused it)
ERROR 2025-05-16 19:24:44,793 basehttp 41832 16744 "POST /api/v1/books/rating/create/ HTTP/1.1" 500 328738
ERROR 2025-05-16 19:25:21,815 log 41832 16744 Internal Server Error: /api/v1/books/rating/create/
Traceback (most recent call last):
  File "C:\Users\ahmed\AppData\Local\Programs\Python\Python312\Lib\site-packages\urllib3\connection.py", line 174, in _new_conn
    conn = connection.create_connection(
           ^^^^^^^^^^^^^^^^^^^^^^^^^^^^^
  File "C:\Users\ahmed\AppData\Local\Programs\Python\Python312\Lib\site-packages\urllib3\util\connection.py", line 95, in create_connection
    raise err
  File "C:\Users\ahmed\AppData\Local\Programs\Python\Python312\Lib\site-packages\urllib3\util\connection.py", line 85, in create_connection
    sock.connect(sa)
ConnectionRefusedError: [WinError 10061] No connection could be made because the target machine actively refused it

During handling of the above exception, another exception occurred:

Traceback (most recent call last):
  File "C:\Users\ahmed\AppData\Local\Programs\Python\Python312\Lib\site-packages\elasticsearch\connection\http_urllib3.py", line 255, in perform_request
    response = self.pool.urlopen(
               ^^^^^^^^^^^^^^^^^^
  File "C:\Users\ahmed\AppData\Local\Programs\Python\Python312\Lib\site-packages\urllib3\connectionpool.py", line 802, in urlopen
    retries = retries.increment(
              ^^^^^^^^^^^^^^^^^^
  File "C:\Users\ahmed\AppData\Local\Programs\Python\Python312\Lib\site-packages\urllib3\util\retry.py", line 527, in increment
    raise six.reraise(type(error), error, _stacktrace)
          ^^^^^^^^^^^^^^^^^^^^^^^^^^^^^^^^^^^^^^^^^^^^
  File "C:\Users\ahmed\AppData\Local\Programs\Python\Python312\Lib\site-packages\urllib3\packages\six.py", line 770, in reraise
    raise value
  File "C:\Users\ahmed\AppData\Local\Programs\Python\Python312\Lib\site-packages\urllib3\connectionpool.py", line 716, in urlopen
    httplib_response = self._make_request(
                       ^^^^^^^^^^^^^^^^^^^
  File "C:\Users\ahmed\AppData\Local\Programs\Python\Python312\Lib\site-packages\urllib3\connectionpool.py", line 416, in _make_request
    conn.request(method, url, **httplib_request_kw)
  File "C:\Users\ahmed\AppData\Local\Programs\Python\Python312\Lib\site-packages\urllib3\connection.py", line 244, in request
    super(HTTPConnection, self).request(method, url, body=body, headers=headers)
  File "C:\Users\ahmed\AppData\Local\Programs\Python\Python312\Lib\http\client.py", line 1319, in request
    self._send_request(method, url, body, headers, encode_chunked)
  File "C:\Users\ahmed\AppData\Local\Programs\Python\Python312\Lib\http\client.py", line 1365, in _send_request
    self.endheaders(body, encode_chunked=encode_chunked)
  File "C:\Users\ahmed\AppData\Local\Programs\Python\Python312\Lib\http\client.py", line 1314, in endheaders
    self._send_output(message_body, encode_chunked=encode_chunked)
  File "C:\Users\ahmed\AppData\Local\Programs\Python\Python312\Lib\http\client.py", line 1074, in _send_output
    self.send(msg)
  File "C:\Users\ahmed\AppData\Local\Programs\Python\Python312\Lib\http\client.py", line 1018, in send
    self.connect()
  File "C:\Users\ahmed\AppData\Local\Programs\Python\Python312\Lib\site-packages\urllib3\connection.py", line 205, in connect
    conn = self._new_conn()
           ^^^^^^^^^^^^^^^^
  File "C:\Users\ahmed\AppData\Local\Programs\Python\Python312\Lib\site-packages\urllib3\connection.py", line 186, in _new_conn
    raise NewConnectionError(
urllib3.exceptions.NewConnectionError: <urllib3.connection.HTTPConnection object at 0x0000020B4A31ED80>: Failed to establish a new connection: [WinError 10061] No connection could be made because the target machine actively refused it

During handling of the above exception, another exception occurred:

Traceback (most recent call last):
  File "C:\Users\ahmed\AppData\Local\Programs\Python\Python312\Lib\site-packages\django\core\handlers\exception.py", line 55, in inner
    response = get_response(request)
               ^^^^^^^^^^^^^^^^^^^^^
  File "C:\Users\ahmed\AppData\Local\Programs\Python\Python312\Lib\site-packages\django\core\handlers\base.py", line 197, in _get_response
    response = wrapped_callback(request, *callback_args, **callback_kwargs)
               ^^^^^^^^^^^^^^^^^^^^^^^^^^^^^^^^^^^^^^^^^^^^^^^^^^^^^^^^^^^^
  File "C:\Users\ahmed\AppData\Local\Programs\Python\Python312\Lib\site-packages\django\views\decorators\csrf.py", line 65, in _view_wrapper
    return view_func(request, *args, **kwargs)
           ^^^^^^^^^^^^^^^^^^^^^^^^^^^^^^^^^^^
  File "C:\Users\ahmed\AppData\Local\Programs\Python\Python312\Lib\site-packages\django\views\generic\base.py", line 104, in view
    return self.dispatch(request, *args, **kwargs)
           ^^^^^^^^^^^^^^^^^^^^^^^^^^^^^^^^^^^^^^^
  File "C:\Users\ahmed\AppData\Local\Programs\Python\Python312\Lib\site-packages\rest_framework\views.py", line 509, in dispatch
    response = self.handle_exception(exc)
               ^^^^^^^^^^^^^^^^^^^^^^^^^^
  File "C:\Users\ahmed\AppData\Local\Programs\Python\Python312\Lib\site-packages\rest_framework\views.py", line 469, in handle_exception
    self.raise_uncaught_exception(exc)
  File "C:\Users\ahmed\AppData\Local\Programs\Python\Python312\Lib\site-packages\rest_framework\views.py", line 480, in raise_uncaught_exception
    raise exc
  File "C:\Users\ahmed\AppData\Local\Programs\Python\Python312\Lib\site-packages\rest_framework\views.py", line 506, in dispatch
    response = handler(request, *args, **kwargs)
               ^^^^^^^^^^^^^^^^^^^^^^^^^^^^^^^^^
  File "C:\Users\ahmed\AppData\Local\Programs\Python\Python312\Lib\site-packages\rest_framework\generics.py", line 194, in post
    return self.create(request, *args, **kwargs)
           ^^^^^^^^^^^^^^^^^^^^^^^^^^^^^^^^^^^^^
  File "C:\Users\ahmed\AppData\Local\Programs\Python\Python312\Lib\site-packages\rest_framework\mixins.py", line 19, in create
    self.perform_create(serializer)
  File "A:\web django\GradProject\New folder\BookNest\BookNest\books\views\review_views.py", line 156, in perform_create
    serializer.save(user=self.request.user, book=book)
  File "C:\Users\ahmed\AppData\Local\Programs\Python\Python312\Lib\site-packages\rest_framework\serializers.py", line 208, in save
    self.instance = self.create(validated_data)
                    ^^^^^^^^^^^^^^^^^^^^^^^^^^^
  File "A:\web django\GradProject\New folder\BookNest\BookNest\books\serializers\review_serializers.py", line 83, in create
    book.save()
  File "C:\Users\ahmed\AppData\Local\Programs\Python\Python312\Lib\site-packages\django\db\models\base.py", line 891, in save
    self.save_base(
  File "C:\Users\ahmed\AppData\Local\Programs\Python\Python312\Lib\site-packages\django\db\models\base.py", line 1012, in save_base
    post_save.send(
  File "C:\Users\ahmed\AppData\Local\Programs\Python\Python312\Lib\site-packages\django\dispatch\dispatcher.py", line 189, in send
    response = receiver(signal=self, sender=sender, **named)
               ^^^^^^^^^^^^^^^^^^^^^^^^^^^^^^^^^^^^^^^^^^^^^
  File "C:\Users\ahmed\AppData\Local\Programs\Python\Python312\Lib\site-packages\django_elasticsearch_dsl\signals.py", line 61, in handle_save
    registry.update(instance)
  File "C:\Users\ahmed\AppData\Local\Programs\Python\Python312\Lib\site-packages\django_elasticsearch_dsl\registries.py", line 141, in update
    doc().update(instance, **kwargs)
  File "C:\Users\ahmed\AppData\Local\Programs\Python\Python312\Lib\site-packages\django_elasticsearch_dsl\documents.py", line 259, in update
    return self._bulk(
           ^^^^^^^^^^^
  File "C:\Users\ahmed\AppData\Local\Programs\Python\Python312\Lib\site-packages\django_elasticsearch_dsl\documents.py", line 236, in _bulk
    return self.bulk(*args, **kwargs)
           ^^^^^^^^^^^^^^^^^^^^^^^^^^
  File "C:\Users\ahmed\AppData\Local\Programs\Python\Python312\Lib\site-packages\django_elasticsearch_dsl\documents.py", line 178, in bulk
    response = bulk(client=self._get_connection(), actions=actions, **kwargs)
               ^^^^^^^^^^^^^^^^^^^^^^^^^^^^^^^^^^^^^^^^^^^^^^^^^^^^^^^^^^^^^^
  File "C:\Users\ahmed\AppData\Local\Programs\Python\Python312\Lib\site-packages\elasticsearch\helpers\actions.py", line 410, in bulk
    for ok, item in streaming_bulk(
  File "C:\Users\ahmed\AppData\Local\Programs\Python\Python312\Lib\site-packages\elasticsearch\helpers\actions.py", line 329, in streaming_bulk
    for data, (ok, info) in zip(
  File "C:\Users\ahmed\AppData\Local\Programs\Python\Python312\Lib\site-packages\elasticsearch\helpers\actions.py", line 256, in _process_bulk_chunk
    for item in gen:
  File "C:\Users\ahmed\AppData\Local\Programs\Python\Python312\Lib\site-packages\elasticsearch\helpers\actions.py", line 195, in _process_bulk_chunk_error
    raise error
  File "C:\Users\ahmed\AppData\Local\Programs\Python\Python312\Lib\site-packages\elasticsearch\helpers\actions.py", line 240, in _process_bulk_chunk
    resp = client.bulk(*args, body="\n".join(bulk_actions) + "\n", **kwargs)
           ^^^^^^^^^^^^^^^^^^^^^^^^^^^^^^^^^^^^^^^^^^^^^^^^^^^^^^^^^^^^^^^^^
  File "C:\Users\ahmed\AppData\Local\Programs\Python\Python312\Lib\site-packages\elasticsearch\client\utils.py", line 347, in _wrapped
    return func(*args, params=params, headers=headers, **kwargs)
           ^^^^^^^^^^^^^^^^^^^^^^^^^^^^^^^^^^^^^^^^^^^^^^^^^^^^^
  File "C:\Users\ahmed\AppData\Local\Programs\Python\Python312\Lib\site-packages\elasticsearch\client\__init__.py", line 472, in bulk
    return self.transport.perform_request(
           ^^^^^^^^^^^^^^^^^^^^^^^^^^^^^^^
  File "C:\Users\ahmed\AppData\Local\Programs\Python\Python312\Lib\site-packages\elasticsearch\transport.py", line 417, in perform_request
    self._do_verify_elasticsearch(headers=headers, timeout=timeout)
  File "C:\Users\ahmed\AppData\Local\Programs\Python\Python312\Lib\site-packages\elasticsearch\transport.py", line 606, in _do_verify_elasticsearch
    raise error
  File "C:\Users\ahmed\AppData\Local\Programs\Python\Python312\Lib\site-packages\elasticsearch\transport.py", line 569, in _do_verify_elasticsearch
    _, info_headers, info_response = conn.perform_request(
                                     ^^^^^^^^^^^^^^^^^^^^^
  File "C:\Users\ahmed\AppData\Local\Programs\Python\Python312\Lib\site-packages\elasticsearch\connection\http_urllib3.py", line 280, in perform_request
    raise ConnectionError("N/A", str(e), e)
elasticsearch.exceptions.ConnectionError: ConnectionError(<urllib3.connection.HTTPConnection object at 0x0000020B4A31ED80>: Failed to establish a new connection: [WinError 10061] No connection could be made because the target machine actively refused it) caused by: NewConnectionError(<urllib3.connection.HTTPConnection object at 0x0000020B4A31ED80>: Failed to establish a new connection: [WinError 10061] No connection could be made because the target machine actively refused it)
ERROR 2025-05-16 19:25:21,836 basehttp 41832 16744 "POST /api/v1/books/rating/create/ HTTP/1.1" 500 332302
ERROR 2025-05-16 19:25:33,324 log 41832 16744 Internal Server Error: /api/v1/books/rating/create/
Traceback (most recent call last):
  File "C:\Users\ahmed\AppData\Local\Programs\Python\Python312\Lib\site-packages\urllib3\connection.py", line 174, in _new_conn
    conn = connection.create_connection(
           ^^^^^^^^^^^^^^^^^^^^^^^^^^^^^
  File "C:\Users\ahmed\AppData\Local\Programs\Python\Python312\Lib\site-packages\urllib3\util\connection.py", line 95, in create_connection
    raise err
  File "C:\Users\ahmed\AppData\Local\Programs\Python\Python312\Lib\site-packages\urllib3\util\connection.py", line 85, in create_connection
    sock.connect(sa)
ConnectionRefusedError: [WinError 10061] No connection could be made because the target machine actively refused it

During handling of the above exception, another exception occurred:

Traceback (most recent call last):
  File "C:\Users\ahmed\AppData\Local\Programs\Python\Python312\Lib\site-packages\elasticsearch\connection\http_urllib3.py", line 255, in perform_request
    response = self.pool.urlopen(
               ^^^^^^^^^^^^^^^^^^
  File "C:\Users\ahmed\AppData\Local\Programs\Python\Python312\Lib\site-packages\urllib3\connectionpool.py", line 802, in urlopen
    retries = retries.increment(
              ^^^^^^^^^^^^^^^^^^
  File "C:\Users\ahmed\AppData\Local\Programs\Python\Python312\Lib\site-packages\urllib3\util\retry.py", line 527, in increment
    raise six.reraise(type(error), error, _stacktrace)
          ^^^^^^^^^^^^^^^^^^^^^^^^^^^^^^^^^^^^^^^^^^^^
  File "C:\Users\ahmed\AppData\Local\Programs\Python\Python312\Lib\site-packages\urllib3\packages\six.py", line 770, in reraise
    raise value
  File "C:\Users\ahmed\AppData\Local\Programs\Python\Python312\Lib\site-packages\urllib3\connectionpool.py", line 716, in urlopen
    httplib_response = self._make_request(
                       ^^^^^^^^^^^^^^^^^^^
  File "C:\Users\ahmed\AppData\Local\Programs\Python\Python312\Lib\site-packages\urllib3\connectionpool.py", line 416, in _make_request
    conn.request(method, url, **httplib_request_kw)
  File "C:\Users\ahmed\AppData\Local\Programs\Python\Python312\Lib\site-packages\urllib3\connection.py", line 244, in request
    super(HTTPConnection, self).request(method, url, body=body, headers=headers)
  File "C:\Users\ahmed\AppData\Local\Programs\Python\Python312\Lib\http\client.py", line 1319, in request
    self._send_request(method, url, body, headers, encode_chunked)
  File "C:\Users\ahmed\AppData\Local\Programs\Python\Python312\Lib\http\client.py", line 1365, in _send_request
    self.endheaders(body, encode_chunked=encode_chunked)
  File "C:\Users\ahmed\AppData\Local\Programs\Python\Python312\Lib\http\client.py", line 1314, in endheaders
    self._send_output(message_body, encode_chunked=encode_chunked)
  File "C:\Users\ahmed\AppData\Local\Programs\Python\Python312\Lib\http\client.py", line 1074, in _send_output
    self.send(msg)
  File "C:\Users\ahmed\AppData\Local\Programs\Python\Python312\Lib\http\client.py", line 1018, in send
    self.connect()
  File "C:\Users\ahmed\AppData\Local\Programs\Python\Python312\Lib\site-packages\urllib3\connection.py", line 205, in connect
    conn = self._new_conn()
           ^^^^^^^^^^^^^^^^
  File "C:\Users\ahmed\AppData\Local\Programs\Python\Python312\Lib\site-packages\urllib3\connection.py", line 186, in _new_conn
    raise NewConnectionError(
urllib3.exceptions.NewConnectionError: <urllib3.connection.HTTPConnection object at 0x0000020B4A166E10>: Failed to establish a new connection: [WinError 10061] No connection could be made because the target machine actively refused it

During handling of the above exception, another exception occurred:

Traceback (most recent call last):
  File "C:\Users\ahmed\AppData\Local\Programs\Python\Python312\Lib\site-packages\django\core\handlers\exception.py", line 55, in inner
    response = get_response(request)
               ^^^^^^^^^^^^^^^^^^^^^
  File "C:\Users\ahmed\AppData\Local\Programs\Python\Python312\Lib\site-packages\django\core\handlers\base.py", line 197, in _get_response
    response = wrapped_callback(request, *callback_args, **callback_kwargs)
               ^^^^^^^^^^^^^^^^^^^^^^^^^^^^^^^^^^^^^^^^^^^^^^^^^^^^^^^^^^^^
  File "C:\Users\ahmed\AppData\Local\Programs\Python\Python312\Lib\site-packages\django\views\decorators\csrf.py", line 65, in _view_wrapper
    return view_func(request, *args, **kwargs)
           ^^^^^^^^^^^^^^^^^^^^^^^^^^^^^^^^^^^
  File "C:\Users\ahmed\AppData\Local\Programs\Python\Python312\Lib\site-packages\django\views\generic\base.py", line 104, in view
    return self.dispatch(request, *args, **kwargs)
           ^^^^^^^^^^^^^^^^^^^^^^^^^^^^^^^^^^^^^^^
  File "C:\Users\ahmed\AppData\Local\Programs\Python\Python312\Lib\site-packages\rest_framework\views.py", line 509, in dispatch
    response = self.handle_exception(exc)
               ^^^^^^^^^^^^^^^^^^^^^^^^^^
  File "C:\Users\ahmed\AppData\Local\Programs\Python\Python312\Lib\site-packages\rest_framework\views.py", line 469, in handle_exception
    self.raise_uncaught_exception(exc)
  File "C:\Users\ahmed\AppData\Local\Programs\Python\Python312\Lib\site-packages\rest_framework\views.py", line 480, in raise_uncaught_exception
    raise exc
  File "C:\Users\ahmed\AppData\Local\Programs\Python\Python312\Lib\site-packages\rest_framework\views.py", line 506, in dispatch
    response = handler(request, *args, **kwargs)
               ^^^^^^^^^^^^^^^^^^^^^^^^^^^^^^^^^
  File "C:\Users\ahmed\AppData\Local\Programs\Python\Python312\Lib\site-packages\rest_framework\generics.py", line 194, in post
    return self.create(request, *args, **kwargs)
           ^^^^^^^^^^^^^^^^^^^^^^^^^^^^^^^^^^^^^
  File "C:\Users\ahmed\AppData\Local\Programs\Python\Python312\Lib\site-packages\rest_framework\mixins.py", line 19, in create
    self.perform_create(serializer)
  File "A:\web django\GradProject\New folder\BookNest\BookNest\books\views\review_views.py", line 156, in perform_create
    serializer.save(user=self.request.user, book=book)
  File "C:\Users\ahmed\AppData\Local\Programs\Python\Python312\Lib\site-packages\rest_framework\serializers.py", line 208, in save
    self.instance = self.create(validated_data)
                    ^^^^^^^^^^^^^^^^^^^^^^^^^^^
  File "A:\web django\GradProject\New folder\BookNest\BookNest\books\serializers\review_serializers.py", line 83, in create
    book.save()
  File "C:\Users\ahmed\AppData\Local\Programs\Python\Python312\Lib\site-packages\django\db\models\base.py", line 891, in save
    self.save_base(
  File "C:\Users\ahmed\AppData\Local\Programs\Python\Python312\Lib\site-packages\django\db\models\base.py", line 1012, in save_base
    post_save.send(
  File "C:\Users\ahmed\AppData\Local\Programs\Python\Python312\Lib\site-packages\django\dispatch\dispatcher.py", line 189, in send
    response = receiver(signal=self, sender=sender, **named)
               ^^^^^^^^^^^^^^^^^^^^^^^^^^^^^^^^^^^^^^^^^^^^^
  File "C:\Users\ahmed\AppData\Local\Programs\Python\Python312\Lib\site-packages\django_elasticsearch_dsl\signals.py", line 61, in handle_save
    registry.update(instance)
  File "C:\Users\ahmed\AppData\Local\Programs\Python\Python312\Lib\site-packages\django_elasticsearch_dsl\registries.py", line 141, in update
    doc().update(instance, **kwargs)
  File "C:\Users\ahmed\AppData\Local\Programs\Python\Python312\Lib\site-packages\django_elasticsearch_dsl\documents.py", line 259, in update
    return self._bulk(
           ^^^^^^^^^^^
  File "C:\Users\ahmed\AppData\Local\Programs\Python\Python312\Lib\site-packages\django_elasticsearch_dsl\documents.py", line 236, in _bulk
    return self.bulk(*args, **kwargs)
           ^^^^^^^^^^^^^^^^^^^^^^^^^^
  File "C:\Users\ahmed\AppData\Local\Programs\Python\Python312\Lib\site-packages\django_elasticsearch_dsl\documents.py", line 178, in bulk
    response = bulk(client=self._get_connection(), actions=actions, **kwargs)
               ^^^^^^^^^^^^^^^^^^^^^^^^^^^^^^^^^^^^^^^^^^^^^^^^^^^^^^^^^^^^^^
  File "C:\Users\ahmed\AppData\Local\Programs\Python\Python312\Lib\site-packages\elasticsearch\helpers\actions.py", line 410, in bulk
    for ok, item in streaming_bulk(
  File "C:\Users\ahmed\AppData\Local\Programs\Python\Python312\Lib\site-packages\elasticsearch\helpers\actions.py", line 329, in streaming_bulk
    for data, (ok, info) in zip(
  File "C:\Users\ahmed\AppData\Local\Programs\Python\Python312\Lib\site-packages\elasticsearch\helpers\actions.py", line 256, in _process_bulk_chunk
    for item in gen:
  File "C:\Users\ahmed\AppData\Local\Programs\Python\Python312\Lib\site-packages\elasticsearch\helpers\actions.py", line 195, in _process_bulk_chunk_error
    raise error
  File "C:\Users\ahmed\AppData\Local\Programs\Python\Python312\Lib\site-packages\elasticsearch\helpers\actions.py", line 240, in _process_bulk_chunk
    resp = client.bulk(*args, body="\n".join(bulk_actions) + "\n", **kwargs)
           ^^^^^^^^^^^^^^^^^^^^^^^^^^^^^^^^^^^^^^^^^^^^^^^^^^^^^^^^^^^^^^^^^
  File "C:\Users\ahmed\AppData\Local\Programs\Python\Python312\Lib\site-packages\elasticsearch\client\utils.py", line 347, in _wrapped
    return func(*args, params=params, headers=headers, **kwargs)
           ^^^^^^^^^^^^^^^^^^^^^^^^^^^^^^^^^^^^^^^^^^^^^^^^^^^^^
  File "C:\Users\ahmed\AppData\Local\Programs\Python\Python312\Lib\site-packages\elasticsearch\client\__init__.py", line 472, in bulk
    return self.transport.perform_request(
           ^^^^^^^^^^^^^^^^^^^^^^^^^^^^^^^
  File "C:\Users\ahmed\AppData\Local\Programs\Python\Python312\Lib\site-packages\elasticsearch\transport.py", line 417, in perform_request
    self._do_verify_elasticsearch(headers=headers, timeout=timeout)
  File "C:\Users\ahmed\AppData\Local\Programs\Python\Python312\Lib\site-packages\elasticsearch\transport.py", line 606, in _do_verify_elasticsearch
    raise error
  File "C:\Users\ahmed\AppData\Local\Programs\Python\Python312\Lib\site-packages\elasticsearch\transport.py", line 569, in _do_verify_elasticsearch
    _, info_headers, info_response = conn.perform_request(
                                     ^^^^^^^^^^^^^^^^^^^^^
  File "C:\Users\ahmed\AppData\Local\Programs\Python\Python312\Lib\site-packages\elasticsearch\connection\http_urllib3.py", line 280, in perform_request
    raise ConnectionError("N/A", str(e), e)
elasticsearch.exceptions.ConnectionError: ConnectionError(<urllib3.connection.HTTPConnection object at 0x0000020B4A166E10>: Failed to establish a new connection: [WinError 10061] No connection could be made because the target machine actively refused it) caused by: NewConnectionError(<urllib3.connection.HTTPConnection object at 0x0000020B4A166E10>: Failed to establish a new connection: [WinError 10061] No connection could be made because the target machine actively refused it)
ERROR 2025-05-16 19:25:33,350 basehttp 41832 16744 "POST /api/v1/books/rating/create/ HTTP/1.1" 500 336276
ERROR 2025-05-16 19:25:37,648 log 41832 16744 Internal Server Error: /api/v1/books/rating/create/
Traceback (most recent call last):
  File "C:\Users\ahmed\AppData\Local\Programs\Python\Python312\Lib\site-packages\urllib3\connection.py", line 174, in _new_conn
    conn = connection.create_connection(
           ^^^^^^^^^^^^^^^^^^^^^^^^^^^^^
  File "C:\Users\ahmed\AppData\Local\Programs\Python\Python312\Lib\site-packages\urllib3\util\connection.py", line 95, in create_connection
    raise err
  File "C:\Users\ahmed\AppData\Local\Programs\Python\Python312\Lib\site-packages\urllib3\util\connection.py", line 85, in create_connection
    sock.connect(sa)
ConnectionRefusedError: [WinError 10061] No connection could be made because the target machine actively refused it

During handling of the above exception, another exception occurred:

Traceback (most recent call last):
  File "C:\Users\ahmed\AppData\Local\Programs\Python\Python312\Lib\site-packages\elasticsearch\connection\http_urllib3.py", line 255, in perform_request
    response = self.pool.urlopen(
               ^^^^^^^^^^^^^^^^^^
  File "C:\Users\ahmed\AppData\Local\Programs\Python\Python312\Lib\site-packages\urllib3\connectionpool.py", line 802, in urlopen
    retries = retries.increment(
              ^^^^^^^^^^^^^^^^^^
  File "C:\Users\ahmed\AppData\Local\Programs\Python\Python312\Lib\site-packages\urllib3\util\retry.py", line 527, in increment
    raise six.reraise(type(error), error, _stacktrace)
          ^^^^^^^^^^^^^^^^^^^^^^^^^^^^^^^^^^^^^^^^^^^^
  File "C:\Users\ahmed\AppData\Local\Programs\Python\Python312\Lib\site-packages\urllib3\packages\six.py", line 770, in reraise
    raise value
  File "C:\Users\ahmed\AppData\Local\Programs\Python\Python312\Lib\site-packages\urllib3\connectionpool.py", line 716, in urlopen
    httplib_response = self._make_request(
                       ^^^^^^^^^^^^^^^^^^^
  File "C:\Users\ahmed\AppData\Local\Programs\Python\Python312\Lib\site-packages\urllib3\connectionpool.py", line 416, in _make_request
    conn.request(method, url, **httplib_request_kw)
  File "C:\Users\ahmed\AppData\Local\Programs\Python\Python312\Lib\site-packages\urllib3\connection.py", line 244, in request
    super(HTTPConnection, self).request(method, url, body=body, headers=headers)
  File "C:\Users\ahmed\AppData\Local\Programs\Python\Python312\Lib\http\client.py", line 1319, in request
    self._send_request(method, url, body, headers, encode_chunked)
  File "C:\Users\ahmed\AppData\Local\Programs\Python\Python312\Lib\http\client.py", line 1365, in _send_request
    self.endheaders(body, encode_chunked=encode_chunked)
  File "C:\Users\ahmed\AppData\Local\Programs\Python\Python312\Lib\http\client.py", line 1314, in endheaders
    self._send_output(message_body, encode_chunked=encode_chunked)
  File "C:\Users\ahmed\AppData\Local\Programs\Python\Python312\Lib\http\client.py", line 1074, in _send_output
    self.send(msg)
  File "C:\Users\ahmed\AppData\Local\Programs\Python\Python312\Lib\http\client.py", line 1018, in send
    self.connect()
  File "C:\Users\ahmed\AppData\Local\Programs\Python\Python312\Lib\site-packages\urllib3\connection.py", line 205, in connect
    conn = self._new_conn()
           ^^^^^^^^^^^^^^^^
  File "C:\Users\ahmed\AppData\Local\Programs\Python\Python312\Lib\site-packages\urllib3\connection.py", line 186, in _new_conn
    raise NewConnectionError(
urllib3.exceptions.NewConnectionError: <urllib3.connection.HTTPConnection object at 0x0000020B4A9E6FF0>: Failed to establish a new connection: [WinError 10061] No connection could be made because the target machine actively refused it

During handling of the above exception, another exception occurred:

Traceback (most recent call last):
  File "C:\Users\ahmed\AppData\Local\Programs\Python\Python312\Lib\site-packages\django\core\handlers\exception.py", line 55, in inner
    response = get_response(request)
               ^^^^^^^^^^^^^^^^^^^^^
  File "C:\Users\ahmed\AppData\Local\Programs\Python\Python312\Lib\site-packages\django\core\handlers\base.py", line 197, in _get_response
    response = wrapped_callback(request, *callback_args, **callback_kwargs)
               ^^^^^^^^^^^^^^^^^^^^^^^^^^^^^^^^^^^^^^^^^^^^^^^^^^^^^^^^^^^^
  File "C:\Users\ahmed\AppData\Local\Programs\Python\Python312\Lib\site-packages\django\views\decorators\csrf.py", line 65, in _view_wrapper
    return view_func(request, *args, **kwargs)
           ^^^^^^^^^^^^^^^^^^^^^^^^^^^^^^^^^^^
  File "C:\Users\ahmed\AppData\Local\Programs\Python\Python312\Lib\site-packages\django\views\generic\base.py", line 104, in view
    return self.dispatch(request, *args, **kwargs)
           ^^^^^^^^^^^^^^^^^^^^^^^^^^^^^^^^^^^^^^^
  File "C:\Users\ahmed\AppData\Local\Programs\Python\Python312\Lib\site-packages\rest_framework\views.py", line 509, in dispatch
    response = self.handle_exception(exc)
               ^^^^^^^^^^^^^^^^^^^^^^^^^^
  File "C:\Users\ahmed\AppData\Local\Programs\Python\Python312\Lib\site-packages\rest_framework\views.py", line 469, in handle_exception
    self.raise_uncaught_exception(exc)
  File "C:\Users\ahmed\AppData\Local\Programs\Python\Python312\Lib\site-packages\rest_framework\views.py", line 480, in raise_uncaught_exception
    raise exc
  File "C:\Users\ahmed\AppData\Local\Programs\Python\Python312\Lib\site-packages\rest_framework\views.py", line 506, in dispatch
    response = handler(request, *args, **kwargs)
               ^^^^^^^^^^^^^^^^^^^^^^^^^^^^^^^^^
  File "C:\Users\ahmed\AppData\Local\Programs\Python\Python312\Lib\site-packages\rest_framework\generics.py", line 194, in post
    return self.create(request, *args, **kwargs)
           ^^^^^^^^^^^^^^^^^^^^^^^^^^^^^^^^^^^^^
  File "C:\Users\ahmed\AppData\Local\Programs\Python\Python312\Lib\site-packages\rest_framework\mixins.py", line 19, in create
    self.perform_create(serializer)
  File "A:\web django\GradProject\New folder\BookNest\BookNest\books\views\review_views.py", line 156, in perform_create
    serializer.save(user=self.request.user, book=book)
  File "C:\Users\ahmed\AppData\Local\Programs\Python\Python312\Lib\site-packages\rest_framework\serializers.py", line 208, in save
    self.instance = self.create(validated_data)
                    ^^^^^^^^^^^^^^^^^^^^^^^^^^^
  File "A:\web django\GradProject\New folder\BookNest\BookNest\books\serializers\review_serializers.py", line 83, in create
    book.save()
  File "C:\Users\ahmed\AppData\Local\Programs\Python\Python312\Lib\site-packages\django\db\models\base.py", line 891, in save
    self.save_base(
  File "C:\Users\ahmed\AppData\Local\Programs\Python\Python312\Lib\site-packages\django\db\models\base.py", line 1012, in save_base
    post_save.send(
  File "C:\Users\ahmed\AppData\Local\Programs\Python\Python312\Lib\site-packages\django\dispatch\dispatcher.py", line 189, in send
    response = receiver(signal=self, sender=sender, **named)
               ^^^^^^^^^^^^^^^^^^^^^^^^^^^^^^^^^^^^^^^^^^^^^
  File "C:\Users\ahmed\AppData\Local\Programs\Python\Python312\Lib\site-packages\django_elasticsearch_dsl\signals.py", line 61, in handle_save
    registry.update(instance)
  File "C:\Users\ahmed\AppData\Local\Programs\Python\Python312\Lib\site-packages\django_elasticsearch_dsl\registries.py", line 141, in update
    doc().update(instance, **kwargs)
  File "C:\Users\ahmed\AppData\Local\Programs\Python\Python312\Lib\site-packages\django_elasticsearch_dsl\documents.py", line 259, in update
    return self._bulk(
           ^^^^^^^^^^^
  File "C:\Users\ahmed\AppData\Local\Programs\Python\Python312\Lib\site-packages\django_elasticsearch_dsl\documents.py", line 236, in _bulk
    return self.bulk(*args, **kwargs)
           ^^^^^^^^^^^^^^^^^^^^^^^^^^
  File "C:\Users\ahmed\AppData\Local\Programs\Python\Python312\Lib\site-packages\django_elasticsearch_dsl\documents.py", line 178, in bulk
    response = bulk(client=self._get_connection(), actions=actions, **kwargs)
               ^^^^^^^^^^^^^^^^^^^^^^^^^^^^^^^^^^^^^^^^^^^^^^^^^^^^^^^^^^^^^^
  File "C:\Users\ahmed\AppData\Local\Programs\Python\Python312\Lib\site-packages\elasticsearch\helpers\actions.py", line 410, in bulk
    for ok, item in streaming_bulk(
  File "C:\Users\ahmed\AppData\Local\Programs\Python\Python312\Lib\site-packages\elasticsearch\helpers\actions.py", line 329, in streaming_bulk
    for data, (ok, info) in zip(
  File "C:\Users\ahmed\AppData\Local\Programs\Python\Python312\Lib\site-packages\elasticsearch\helpers\actions.py", line 256, in _process_bulk_chunk
    for item in gen:
  File "C:\Users\ahmed\AppData\Local\Programs\Python\Python312\Lib\site-packages\elasticsearch\helpers\actions.py", line 195, in _process_bulk_chunk_error
    raise error
  File "C:\Users\ahmed\AppData\Local\Programs\Python\Python312\Lib\site-packages\elasticsearch\helpers\actions.py", line 240, in _process_bulk_chunk
    resp = client.bulk(*args, body="\n".join(bulk_actions) + "\n", **kwargs)
           ^^^^^^^^^^^^^^^^^^^^^^^^^^^^^^^^^^^^^^^^^^^^^^^^^^^^^^^^^^^^^^^^^
  File "C:\Users\ahmed\AppData\Local\Programs\Python\Python312\Lib\site-packages\elasticsearch\client\utils.py", line 347, in _wrapped
    return func(*args, params=params, headers=headers, **kwargs)
           ^^^^^^^^^^^^^^^^^^^^^^^^^^^^^^^^^^^^^^^^^^^^^^^^^^^^^
  File "C:\Users\ahmed\AppData\Local\Programs\Python\Python312\Lib\site-packages\elasticsearch\client\__init__.py", line 472, in bulk
    return self.transport.perform_request(
           ^^^^^^^^^^^^^^^^^^^^^^^^^^^^^^^
  File "C:\Users\ahmed\AppData\Local\Programs\Python\Python312\Lib\site-packages\elasticsearch\transport.py", line 417, in perform_request
    self._do_verify_elasticsearch(headers=headers, timeout=timeout)
  File "C:\Users\ahmed\AppData\Local\Programs\Python\Python312\Lib\site-packages\elasticsearch\transport.py", line 606, in _do_verify_elasticsearch
    raise error
  File "C:\Users\ahmed\AppData\Local\Programs\Python\Python312\Lib\site-packages\elasticsearch\transport.py", line 569, in _do_verify_elasticsearch
    _, info_headers, info_response = conn.perform_request(
                                     ^^^^^^^^^^^^^^^^^^^^^
  File "C:\Users\ahmed\AppData\Local\Programs\Python\Python312\Lib\site-packages\elasticsearch\connection\http_urllib3.py", line 280, in perform_request
    raise ConnectionError("N/A", str(e), e)
elasticsearch.exceptions.ConnectionError: ConnectionError(<urllib3.connection.HTTPConnection object at 0x0000020B4A9E6FF0>: Failed to establish a new connection: [WinError 10061] No connection could be made because the target machine actively refused it) caused by: NewConnectionError(<urllib3.connection.HTTPConnection object at 0x0000020B4A9E6FF0>: Failed to establish a new connection: [WinError 10061] No connection could be made because the target machine actively refused it)
ERROR 2025-05-16 19:25:37,659 basehttp 41832 16744 "POST /api/v1/books/rating/create/ HTTP/1.1" 500 337540
ERROR 2025-05-16 19:25:41,356 log 41832 16744 Internal Server Error: /api/v1/books/rating/create/
Traceback (most recent call last):
  File "C:\Users\ahmed\AppData\Local\Programs\Python\Python312\Lib\site-packages\urllib3\connection.py", line 174, in _new_conn
    conn = connection.create_connection(
           ^^^^^^^^^^^^^^^^^^^^^^^^^^^^^
  File "C:\Users\ahmed\AppData\Local\Programs\Python\Python312\Lib\site-packages\urllib3\util\connection.py", line 95, in create_connection
    raise err
  File "C:\Users\ahmed\AppData\Local\Programs\Python\Python312\Lib\site-packages\urllib3\util\connection.py", line 85, in create_connection
    sock.connect(sa)
ConnectionRefusedError: [WinError 10061] No connection could be made because the target machine actively refused it

During handling of the above exception, another exception occurred:

Traceback (most recent call last):
  File "C:\Users\ahmed\AppData\Local\Programs\Python\Python312\Lib\site-packages\elasticsearch\connection\http_urllib3.py", line 255, in perform_request
    response = self.pool.urlopen(
               ^^^^^^^^^^^^^^^^^^
  File "C:\Users\ahmed\AppData\Local\Programs\Python\Python312\Lib\site-packages\urllib3\connectionpool.py", line 802, in urlopen
    retries = retries.increment(
              ^^^^^^^^^^^^^^^^^^
  File "C:\Users\ahmed\AppData\Local\Programs\Python\Python312\Lib\site-packages\urllib3\util\retry.py", line 527, in increment
    raise six.reraise(type(error), error, _stacktrace)
          ^^^^^^^^^^^^^^^^^^^^^^^^^^^^^^^^^^^^^^^^^^^^
  File "C:\Users\ahmed\AppData\Local\Programs\Python\Python312\Lib\site-packages\urllib3\packages\six.py", line 770, in reraise
    raise value
  File "C:\Users\ahmed\AppData\Local\Programs\Python\Python312\Lib\site-packages\urllib3\connectionpool.py", line 716, in urlopen
    httplib_response = self._make_request(
                       ^^^^^^^^^^^^^^^^^^^
  File "C:\Users\ahmed\AppData\Local\Programs\Python\Python312\Lib\site-packages\urllib3\connectionpool.py", line 416, in _make_request
    conn.request(method, url, **httplib_request_kw)
  File "C:\Users\ahmed\AppData\Local\Programs\Python\Python312\Lib\site-packages\urllib3\connection.py", line 244, in request
    super(HTTPConnection, self).request(method, url, body=body, headers=headers)
  File "C:\Users\ahmed\AppData\Local\Programs\Python\Python312\Lib\http\client.py", line 1319, in request
    self._send_request(method, url, body, headers, encode_chunked)
  File "C:\Users\ahmed\AppData\Local\Programs\Python\Python312\Lib\http\client.py", line 1365, in _send_request
    self.endheaders(body, encode_chunked=encode_chunked)
  File "C:\Users\ahmed\AppData\Local\Programs\Python\Python312\Lib\http\client.py", line 1314, in endheaders
    self._send_output(message_body, encode_chunked=encode_chunked)
  File "C:\Users\ahmed\AppData\Local\Programs\Python\Python312\Lib\http\client.py", line 1074, in _send_output
    self.send(msg)
  File "C:\Users\ahmed\AppData\Local\Programs\Python\Python312\Lib\http\client.py", line 1018, in send
    self.connect()
  File "C:\Users\ahmed\AppData\Local\Programs\Python\Python312\Lib\site-packages\urllib3\connection.py", line 205, in connect
    conn = self._new_conn()
           ^^^^^^^^^^^^^^^^
  File "C:\Users\ahmed\AppData\Local\Programs\Python\Python312\Lib\site-packages\urllib3\connection.py", line 186, in _new_conn
    raise NewConnectionError(
urllib3.exceptions.NewConnectionError: <urllib3.connection.HTTPConnection object at 0x0000020B4A33F4D0>: Failed to establish a new connection: [WinError 10061] No connection could be made because the target machine actively refused it

During handling of the above exception, another exception occurred:

Traceback (most recent call last):
  File "C:\Users\ahmed\AppData\Local\Programs\Python\Python312\Lib\site-packages\django\core\handlers\exception.py", line 55, in inner
    response = get_response(request)
               ^^^^^^^^^^^^^^^^^^^^^
  File "C:\Users\ahmed\AppData\Local\Programs\Python\Python312\Lib\site-packages\django\core\handlers\base.py", line 197, in _get_response
    response = wrapped_callback(request, *callback_args, **callback_kwargs)
               ^^^^^^^^^^^^^^^^^^^^^^^^^^^^^^^^^^^^^^^^^^^^^^^^^^^^^^^^^^^^
  File "C:\Users\ahmed\AppData\Local\Programs\Python\Python312\Lib\site-packages\django\views\decorators\csrf.py", line 65, in _view_wrapper
    return view_func(request, *args, **kwargs)
           ^^^^^^^^^^^^^^^^^^^^^^^^^^^^^^^^^^^
  File "C:\Users\ahmed\AppData\Local\Programs\Python\Python312\Lib\site-packages\django\views\generic\base.py", line 104, in view
    return self.dispatch(request, *args, **kwargs)
           ^^^^^^^^^^^^^^^^^^^^^^^^^^^^^^^^^^^^^^^
  File "C:\Users\ahmed\AppData\Local\Programs\Python\Python312\Lib\site-packages\rest_framework\views.py", line 509, in dispatch
    response = self.handle_exception(exc)
               ^^^^^^^^^^^^^^^^^^^^^^^^^^
  File "C:\Users\ahmed\AppData\Local\Programs\Python\Python312\Lib\site-packages\rest_framework\views.py", line 469, in handle_exception
    self.raise_uncaught_exception(exc)
  File "C:\Users\ahmed\AppData\Local\Programs\Python\Python312\Lib\site-packages\rest_framework\views.py", line 480, in raise_uncaught_exception
    raise exc
  File "C:\Users\ahmed\AppData\Local\Programs\Python\Python312\Lib\site-packages\rest_framework\views.py", line 506, in dispatch
    response = handler(request, *args, **kwargs)
               ^^^^^^^^^^^^^^^^^^^^^^^^^^^^^^^^^
  File "C:\Users\ahmed\AppData\Local\Programs\Python\Python312\Lib\site-packages\rest_framework\generics.py", line 194, in post
    return self.create(request, *args, **kwargs)
           ^^^^^^^^^^^^^^^^^^^^^^^^^^^^^^^^^^^^^
  File "C:\Users\ahmed\AppData\Local\Programs\Python\Python312\Lib\site-packages\rest_framework\mixins.py", line 19, in create
    self.perform_create(serializer)
  File "A:\web django\GradProject\New folder\BookNest\BookNest\books\views\review_views.py", line 156, in perform_create
    serializer.save(user=self.request.user, book=book)
  File "C:\Users\ahmed\AppData\Local\Programs\Python\Python312\Lib\site-packages\rest_framework\serializers.py", line 208, in save
    self.instance = self.create(validated_data)
                    ^^^^^^^^^^^^^^^^^^^^^^^^^^^
  File "A:\web django\GradProject\New folder\BookNest\BookNest\books\serializers\review_serializers.py", line 83, in create
    book.save()
  File "C:\Users\ahmed\AppData\Local\Programs\Python\Python312\Lib\site-packages\django\db\models\base.py", line 891, in save
    self.save_base(
  File "C:\Users\ahmed\AppData\Local\Programs\Python\Python312\Lib\site-packages\django\db\models\base.py", line 1012, in save_base
    post_save.send(
  File "C:\Users\ahmed\AppData\Local\Programs\Python\Python312\Lib\site-packages\django\dispatch\dispatcher.py", line 189, in send
    response = receiver(signal=self, sender=sender, **named)
               ^^^^^^^^^^^^^^^^^^^^^^^^^^^^^^^^^^^^^^^^^^^^^
  File "C:\Users\ahmed\AppData\Local\Programs\Python\Python312\Lib\site-packages\django_elasticsearch_dsl\signals.py", line 61, in handle_save
    registry.update(instance)
  File "C:\Users\ahmed\AppData\Local\Programs\Python\Python312\Lib\site-packages\django_elasticsearch_dsl\registries.py", line 141, in update
    doc().update(instance, **kwargs)
  File "C:\Users\ahmed\AppData\Local\Programs\Python\Python312\Lib\site-packages\django_elasticsearch_dsl\documents.py", line 259, in update
    return self._bulk(
           ^^^^^^^^^^^
  File "C:\Users\ahmed\AppData\Local\Programs\Python\Python312\Lib\site-packages\django_elasticsearch_dsl\documents.py", line 236, in _bulk
    return self.bulk(*args, **kwargs)
           ^^^^^^^^^^^^^^^^^^^^^^^^^^
  File "C:\Users\ahmed\AppData\Local\Programs\Python\Python312\Lib\site-packages\django_elasticsearch_dsl\documents.py", line 178, in bulk
    response = bulk(client=self._get_connection(), actions=actions, **kwargs)
               ^^^^^^^^^^^^^^^^^^^^^^^^^^^^^^^^^^^^^^^^^^^^^^^^^^^^^^^^^^^^^^
  File "C:\Users\ahmed\AppData\Local\Programs\Python\Python312\Lib\site-packages\elasticsearch\helpers\actions.py", line 410, in bulk
    for ok, item in streaming_bulk(
  File "C:\Users\ahmed\AppData\Local\Programs\Python\Python312\Lib\site-packages\elasticsearch\helpers\actions.py", line 329, in streaming_bulk
    for data, (ok, info) in zip(
  File "C:\Users\ahmed\AppData\Local\Programs\Python\Python312\Lib\site-packages\elasticsearch\helpers\actions.py", line 256, in _process_bulk_chunk
    for item in gen:
  File "C:\Users\ahmed\AppData\Local\Programs\Python\Python312\Lib\site-packages\elasticsearch\helpers\actions.py", line 195, in _process_bulk_chunk_error
    raise error
  File "C:\Users\ahmed\AppData\Local\Programs\Python\Python312\Lib\site-packages\elasticsearch\helpers\actions.py", line 240, in _process_bulk_chunk
    resp = client.bulk(*args, body="\n".join(bulk_actions) + "\n", **kwargs)
           ^^^^^^^^^^^^^^^^^^^^^^^^^^^^^^^^^^^^^^^^^^^^^^^^^^^^^^^^^^^^^^^^^
  File "C:\Users\ahmed\AppData\Local\Programs\Python\Python312\Lib\site-packages\elasticsearch\client\utils.py", line 347, in _wrapped
    return func(*args, params=params, headers=headers, **kwargs)
           ^^^^^^^^^^^^^^^^^^^^^^^^^^^^^^^^^^^^^^^^^^^^^^^^^^^^^
  File "C:\Users\ahmed\AppData\Local\Programs\Python\Python312\Lib\site-packages\elasticsearch\client\__init__.py", line 472, in bulk
    return self.transport.perform_request(
           ^^^^^^^^^^^^^^^^^^^^^^^^^^^^^^^
  File "C:\Users\ahmed\AppData\Local\Programs\Python\Python312\Lib\site-packages\elasticsearch\transport.py", line 417, in perform_request
    self._do_verify_elasticsearch(headers=headers, timeout=timeout)
  File "C:\Users\ahmed\AppData\Local\Programs\Python\Python312\Lib\site-packages\elasticsearch\transport.py", line 606, in _do_verify_elasticsearch
    raise error
  File "C:\Users\ahmed\AppData\Local\Programs\Python\Python312\Lib\site-packages\elasticsearch\transport.py", line 569, in _do_verify_elasticsearch
    _, info_headers, info_response = conn.perform_request(
                                     ^^^^^^^^^^^^^^^^^^^^^
  File "C:\Users\ahmed\AppData\Local\Programs\Python\Python312\Lib\site-packages\elasticsearch\connection\http_urllib3.py", line 280, in perform_request
    raise ConnectionError("N/A", str(e), e)
elasticsearch.exceptions.ConnectionError: ConnectionError(<urllib3.connection.HTTPConnection object at 0x0000020B4A33F4D0>: Failed to establish a new connection: [WinError 10061] No connection could be made because the target machine actively refused it) caused by: NewConnectionError(<urllib3.connection.HTTPConnection object at 0x0000020B4A33F4D0>: Failed to establish a new connection: [WinError 10061] No connection could be made because the target machine actively refused it)
ERROR 2025-05-16 19:25:41,366 basehttp 41832 16744 "POST /api/v1/books/rating/create/ HTTP/1.1" 500 346135
ERROR 2025-05-16 19:25:47,921 log 41832 16744 Internal Server Error: /api/v1/books/rating/create/
Traceback (most recent call last):
  File "C:\Users\ahmed\AppData\Local\Programs\Python\Python312\Lib\site-packages\urllib3\connection.py", line 174, in _new_conn
    conn = connection.create_connection(
           ^^^^^^^^^^^^^^^^^^^^^^^^^^^^^
  File "C:\Users\ahmed\AppData\Local\Programs\Python\Python312\Lib\site-packages\urllib3\util\connection.py", line 95, in create_connection
    raise err
  File "C:\Users\ahmed\AppData\Local\Programs\Python\Python312\Lib\site-packages\urllib3\util\connection.py", line 85, in create_connection
    sock.connect(sa)
ConnectionRefusedError: [WinError 10061] No connection could be made because the target machine actively refused it

During handling of the above exception, another exception occurred:

Traceback (most recent call last):
  File "C:\Users\ahmed\AppData\Local\Programs\Python\Python312\Lib\site-packages\elasticsearch\connection\http_urllib3.py", line 255, in perform_request
    response = self.pool.urlopen(
               ^^^^^^^^^^^^^^^^^^
  File "C:\Users\ahmed\AppData\Local\Programs\Python\Python312\Lib\site-packages\urllib3\connectionpool.py", line 802, in urlopen
    retries = retries.increment(
              ^^^^^^^^^^^^^^^^^^
  File "C:\Users\ahmed\AppData\Local\Programs\Python\Python312\Lib\site-packages\urllib3\util\retry.py", line 527, in increment
    raise six.reraise(type(error), error, _stacktrace)
          ^^^^^^^^^^^^^^^^^^^^^^^^^^^^^^^^^^^^^^^^^^^^
  File "C:\Users\ahmed\AppData\Local\Programs\Python\Python312\Lib\site-packages\urllib3\packages\six.py", line 770, in reraise
    raise value
  File "C:\Users\ahmed\AppData\Local\Programs\Python\Python312\Lib\site-packages\urllib3\connectionpool.py", line 716, in urlopen
    httplib_response = self._make_request(
                       ^^^^^^^^^^^^^^^^^^^
  File "C:\Users\ahmed\AppData\Local\Programs\Python\Python312\Lib\site-packages\urllib3\connectionpool.py", line 416, in _make_request
    conn.request(method, url, **httplib_request_kw)
  File "C:\Users\ahmed\AppData\Local\Programs\Python\Python312\Lib\site-packages\urllib3\connection.py", line 244, in request
    super(HTTPConnection, self).request(method, url, body=body, headers=headers)
  File "C:\Users\ahmed\AppData\Local\Programs\Python\Python312\Lib\http\client.py", line 1319, in request
    self._send_request(method, url, body, headers, encode_chunked)
  File "C:\Users\ahmed\AppData\Local\Programs\Python\Python312\Lib\http\client.py", line 1365, in _send_request
    self.endheaders(body, encode_chunked=encode_chunked)
  File "C:\Users\ahmed\AppData\Local\Programs\Python\Python312\Lib\http\client.py", line 1314, in endheaders
    self._send_output(message_body, encode_chunked=encode_chunked)
  File "C:\Users\ahmed\AppData\Local\Programs\Python\Python312\Lib\http\client.py", line 1074, in _send_output
    self.send(msg)
  File "C:\Users\ahmed\AppData\Local\Programs\Python\Python312\Lib\http\client.py", line 1018, in send
    self.connect()
  File "C:\Users\ahmed\AppData\Local\Programs\Python\Python312\Lib\site-packages\urllib3\connection.py", line 205, in connect
    conn = self._new_conn()
           ^^^^^^^^^^^^^^^^
  File "C:\Users\ahmed\AppData\Local\Programs\Python\Python312\Lib\site-packages\urllib3\connection.py", line 186, in _new_conn
    raise NewConnectionError(
urllib3.exceptions.NewConnectionError: <urllib3.connection.HTTPConnection object at 0x0000020B4A38CBC0>: Failed to establish a new connection: [WinError 10061] No connection could be made because the target machine actively refused it

During handling of the above exception, another exception occurred:

Traceback (most recent call last):
  File "C:\Users\ahmed\AppData\Local\Programs\Python\Python312\Lib\site-packages\django\core\handlers\exception.py", line 55, in inner
    response = get_response(request)
               ^^^^^^^^^^^^^^^^^^^^^
  File "C:\Users\ahmed\AppData\Local\Programs\Python\Python312\Lib\site-packages\django\core\handlers\base.py", line 197, in _get_response
    response = wrapped_callback(request, *callback_args, **callback_kwargs)
               ^^^^^^^^^^^^^^^^^^^^^^^^^^^^^^^^^^^^^^^^^^^^^^^^^^^^^^^^^^^^
  File "C:\Users\ahmed\AppData\Local\Programs\Python\Python312\Lib\site-packages\django\views\decorators\csrf.py", line 65, in _view_wrapper
    return view_func(request, *args, **kwargs)
           ^^^^^^^^^^^^^^^^^^^^^^^^^^^^^^^^^^^
  File "C:\Users\ahmed\AppData\Local\Programs\Python\Python312\Lib\site-packages\django\views\generic\base.py", line 104, in view
    return self.dispatch(request, *args, **kwargs)
           ^^^^^^^^^^^^^^^^^^^^^^^^^^^^^^^^^^^^^^^
  File "C:\Users\ahmed\AppData\Local\Programs\Python\Python312\Lib\site-packages\rest_framework\views.py", line 509, in dispatch
    response = self.handle_exception(exc)
               ^^^^^^^^^^^^^^^^^^^^^^^^^^
  File "C:\Users\ahmed\AppData\Local\Programs\Python\Python312\Lib\site-packages\rest_framework\views.py", line 469, in handle_exception
    self.raise_uncaught_exception(exc)
  File "C:\Users\ahmed\AppData\Local\Programs\Python\Python312\Lib\site-packages\rest_framework\views.py", line 480, in raise_uncaught_exception
    raise exc
  File "C:\Users\ahmed\AppData\Local\Programs\Python\Python312\Lib\site-packages\rest_framework\views.py", line 506, in dispatch
    response = handler(request, *args, **kwargs)
               ^^^^^^^^^^^^^^^^^^^^^^^^^^^^^^^^^
  File "C:\Users\ahmed\AppData\Local\Programs\Python\Python312\Lib\site-packages\rest_framework\generics.py", line 194, in post
    return self.create(request, *args, **kwargs)
           ^^^^^^^^^^^^^^^^^^^^^^^^^^^^^^^^^^^^^
  File "C:\Users\ahmed\AppData\Local\Programs\Python\Python312\Lib\site-packages\rest_framework\mixins.py", line 19, in create
    self.perform_create(serializer)
  File "A:\web django\GradProject\New folder\BookNest\BookNest\books\views\review_views.py", line 156, in perform_create
    serializer.save(user=self.request.user, book=book)
  File "C:\Users\ahmed\AppData\Local\Programs\Python\Python312\Lib\site-packages\rest_framework\serializers.py", line 208, in save
    self.instance = self.create(validated_data)
                    ^^^^^^^^^^^^^^^^^^^^^^^^^^^
  File "A:\web django\GradProject\New folder\BookNest\BookNest\books\serializers\review_serializers.py", line 83, in create
    book.save()
  File "C:\Users\ahmed\AppData\Local\Programs\Python\Python312\Lib\site-packages\django\db\models\base.py", line 891, in save
    self.save_base(
  File "C:\Users\ahmed\AppData\Local\Programs\Python\Python312\Lib\site-packages\django\db\models\base.py", line 1012, in save_base
    post_save.send(
  File "C:\Users\ahmed\AppData\Local\Programs\Python\Python312\Lib\site-packages\django\dispatch\dispatcher.py", line 189, in send
    response = receiver(signal=self, sender=sender, **named)
               ^^^^^^^^^^^^^^^^^^^^^^^^^^^^^^^^^^^^^^^^^^^^^
  File "C:\Users\ahmed\AppData\Local\Programs\Python\Python312\Lib\site-packages\django_elasticsearch_dsl\signals.py", line 61, in handle_save
    registry.update(instance)
  File "C:\Users\ahmed\AppData\Local\Programs\Python\Python312\Lib\site-packages\django_elasticsearch_dsl\registries.py", line 141, in update
    doc().update(instance, **kwargs)
  File "C:\Users\ahmed\AppData\Local\Programs\Python\Python312\Lib\site-packages\django_elasticsearch_dsl\documents.py", line 259, in update
    return self._bulk(
           ^^^^^^^^^^^
  File "C:\Users\ahmed\AppData\Local\Programs\Python\Python312\Lib\site-packages\django_elasticsearch_dsl\documents.py", line 236, in _bulk
    return self.bulk(*args, **kwargs)
           ^^^^^^^^^^^^^^^^^^^^^^^^^^
  File "C:\Users\ahmed\AppData\Local\Programs\Python\Python312\Lib\site-packages\django_elasticsearch_dsl\documents.py", line 178, in bulk
    response = bulk(client=self._get_connection(), actions=actions, **kwargs)
               ^^^^^^^^^^^^^^^^^^^^^^^^^^^^^^^^^^^^^^^^^^^^^^^^^^^^^^^^^^^^^^
  File "C:\Users\ahmed\AppData\Local\Programs\Python\Python312\Lib\site-packages\elasticsearch\helpers\actions.py", line 410, in bulk
    for ok, item in streaming_bulk(
  File "C:\Users\ahmed\AppData\Local\Programs\Python\Python312\Lib\site-packages\elasticsearch\helpers\actions.py", line 329, in streaming_bulk
    for data, (ok, info) in zip(
  File "C:\Users\ahmed\AppData\Local\Programs\Python\Python312\Lib\site-packages\elasticsearch\helpers\actions.py", line 256, in _process_bulk_chunk
    for item in gen:
  File "C:\Users\ahmed\AppData\Local\Programs\Python\Python312\Lib\site-packages\elasticsearch\helpers\actions.py", line 195, in _process_bulk_chunk_error
    raise error
  File "C:\Users\ahmed\AppData\Local\Programs\Python\Python312\Lib\site-packages\elasticsearch\helpers\actions.py", line 240, in _process_bulk_chunk
    resp = client.bulk(*args, body="\n".join(bulk_actions) + "\n", **kwargs)
           ^^^^^^^^^^^^^^^^^^^^^^^^^^^^^^^^^^^^^^^^^^^^^^^^^^^^^^^^^^^^^^^^^
  File "C:\Users\ahmed\AppData\Local\Programs\Python\Python312\Lib\site-packages\elasticsearch\client\utils.py", line 347, in _wrapped
    return func(*args, params=params, headers=headers, **kwargs)
           ^^^^^^^^^^^^^^^^^^^^^^^^^^^^^^^^^^^^^^^^^^^^^^^^^^^^^
  File "C:\Users\ahmed\AppData\Local\Programs\Python\Python312\Lib\site-packages\elasticsearch\client\__init__.py", line 472, in bulk
    return self.transport.perform_request(
           ^^^^^^^^^^^^^^^^^^^^^^^^^^^^^^^
  File "C:\Users\ahmed\AppData\Local\Programs\Python\Python312\Lib\site-packages\elasticsearch\transport.py", line 417, in perform_request
    self._do_verify_elasticsearch(headers=headers, timeout=timeout)
  File "C:\Users\ahmed\AppData\Local\Programs\Python\Python312\Lib\site-packages\elasticsearch\transport.py", line 606, in _do_verify_elasticsearch
    raise error
  File "C:\Users\ahmed\AppData\Local\Programs\Python\Python312\Lib\site-packages\elasticsearch\transport.py", line 569, in _do_verify_elasticsearch
    _, info_headers, info_response = conn.perform_request(
                                     ^^^^^^^^^^^^^^^^^^^^^
  File "C:\Users\ahmed\AppData\Local\Programs\Python\Python312\Lib\site-packages\elasticsearch\connection\http_urllib3.py", line 280, in perform_request
    raise ConnectionError("N/A", str(e), e)
elasticsearch.exceptions.ConnectionError: ConnectionError(<urllib3.connection.HTTPConnection object at 0x0000020B4A38CBC0>: Failed to establish a new connection: [WinError 10061] No connection could be made because the target machine actively refused it) caused by: NewConnectionError(<urllib3.connection.HTTPConnection object at 0x0000020B4A38CBC0>: Failed to establish a new connection: [WinError 10061] No connection could be made because the target machine actively refused it)
ERROR 2025-05-16 19:25:47,940 basehttp 41832 16744 "POST /api/v1/books/rating/create/ HTTP/1.1" 500 350530
ERROR 2025-05-16 19:25:54,007 log 41832 16744 Internal Server Error: /api/v1/books/rating/create/
Traceback (most recent call last):
  File "C:\Users\ahmed\AppData\Local\Programs\Python\Python312\Lib\site-packages\urllib3\connection.py", line 174, in _new_conn
    conn = connection.create_connection(
           ^^^^^^^^^^^^^^^^^^^^^^^^^^^^^
  File "C:\Users\ahmed\AppData\Local\Programs\Python\Python312\Lib\site-packages\urllib3\util\connection.py", line 95, in create_connection
    raise err
  File "C:\Users\ahmed\AppData\Local\Programs\Python\Python312\Lib\site-packages\urllib3\util\connection.py", line 85, in create_connection
    sock.connect(sa)
ConnectionRefusedError: [WinError 10061] No connection could be made because the target machine actively refused it

During handling of the above exception, another exception occurred:

Traceback (most recent call last):
  File "C:\Users\ahmed\AppData\Local\Programs\Python\Python312\Lib\site-packages\elasticsearch\connection\http_urllib3.py", line 255, in perform_request
    response = self.pool.urlopen(
               ^^^^^^^^^^^^^^^^^^
  File "C:\Users\ahmed\AppData\Local\Programs\Python\Python312\Lib\site-packages\urllib3\connectionpool.py", line 802, in urlopen
    retries = retries.increment(
              ^^^^^^^^^^^^^^^^^^
  File "C:\Users\ahmed\AppData\Local\Programs\Python\Python312\Lib\site-packages\urllib3\util\retry.py", line 527, in increment
    raise six.reraise(type(error), error, _stacktrace)
          ^^^^^^^^^^^^^^^^^^^^^^^^^^^^^^^^^^^^^^^^^^^^
  File "C:\Users\ahmed\AppData\Local\Programs\Python\Python312\Lib\site-packages\urllib3\packages\six.py", line 770, in reraise
    raise value
  File "C:\Users\ahmed\AppData\Local\Programs\Python\Python312\Lib\site-packages\urllib3\connectionpool.py", line 716, in urlopen
    httplib_response = self._make_request(
                       ^^^^^^^^^^^^^^^^^^^
  File "C:\Users\ahmed\AppData\Local\Programs\Python\Python312\Lib\site-packages\urllib3\connectionpool.py", line 416, in _make_request
    conn.request(method, url, **httplib_request_kw)
  File "C:\Users\ahmed\AppData\Local\Programs\Python\Python312\Lib\site-packages\urllib3\connection.py", line 244, in request
    super(HTTPConnection, self).request(method, url, body=body, headers=headers)
  File "C:\Users\ahmed\AppData\Local\Programs\Python\Python312\Lib\http\client.py", line 1319, in request
    self._send_request(method, url, body, headers, encode_chunked)
  File "C:\Users\ahmed\AppData\Local\Programs\Python\Python312\Lib\http\client.py", line 1365, in _send_request
    self.endheaders(body, encode_chunked=encode_chunked)
  File "C:\Users\ahmed\AppData\Local\Programs\Python\Python312\Lib\http\client.py", line 1314, in endheaders
    self._send_output(message_body, encode_chunked=encode_chunked)
  File "C:\Users\ahmed\AppData\Local\Programs\Python\Python312\Lib\http\client.py", line 1074, in _send_output
    self.send(msg)
  File "C:\Users\ahmed\AppData\Local\Programs\Python\Python312\Lib\http\client.py", line 1018, in send
    self.connect()
  File "C:\Users\ahmed\AppData\Local\Programs\Python\Python312\Lib\site-packages\urllib3\connection.py", line 205, in connect
    conn = self._new_conn()
           ^^^^^^^^^^^^^^^^
  File "C:\Users\ahmed\AppData\Local\Programs\Python\Python312\Lib\site-packages\urllib3\connection.py", line 186, in _new_conn
    raise NewConnectionError(
urllib3.exceptions.NewConnectionError: <urllib3.connection.HTTPConnection object at 0x0000020B4A2489E0>: Failed to establish a new connection: [WinError 10061] No connection could be made because the target machine actively refused it

During handling of the above exception, another exception occurred:

Traceback (most recent call last):
  File "C:\Users\ahmed\AppData\Local\Programs\Python\Python312\Lib\site-packages\django\core\handlers\exception.py", line 55, in inner
    response = get_response(request)
               ^^^^^^^^^^^^^^^^^^^^^
  File "C:\Users\ahmed\AppData\Local\Programs\Python\Python312\Lib\site-packages\django\core\handlers\base.py", line 197, in _get_response
    response = wrapped_callback(request, *callback_args, **callback_kwargs)
               ^^^^^^^^^^^^^^^^^^^^^^^^^^^^^^^^^^^^^^^^^^^^^^^^^^^^^^^^^^^^
  File "C:\Users\ahmed\AppData\Local\Programs\Python\Python312\Lib\site-packages\django\views\decorators\csrf.py", line 65, in _view_wrapper
    return view_func(request, *args, **kwargs)
           ^^^^^^^^^^^^^^^^^^^^^^^^^^^^^^^^^^^
  File "C:\Users\ahmed\AppData\Local\Programs\Python\Python312\Lib\site-packages\django\views\generic\base.py", line 104, in view
    return self.dispatch(request, *args, **kwargs)
           ^^^^^^^^^^^^^^^^^^^^^^^^^^^^^^^^^^^^^^^
  File "C:\Users\ahmed\AppData\Local\Programs\Python\Python312\Lib\site-packages\rest_framework\views.py", line 509, in dispatch
    response = self.handle_exception(exc)
               ^^^^^^^^^^^^^^^^^^^^^^^^^^
  File "C:\Users\ahmed\AppData\Local\Programs\Python\Python312\Lib\site-packages\rest_framework\views.py", line 469, in handle_exception
    self.raise_uncaught_exception(exc)
  File "C:\Users\ahmed\AppData\Local\Programs\Python\Python312\Lib\site-packages\rest_framework\views.py", line 480, in raise_uncaught_exception
    raise exc
  File "C:\Users\ahmed\AppData\Local\Programs\Python\Python312\Lib\site-packages\rest_framework\views.py", line 506, in dispatch
    response = handler(request, *args, **kwargs)
               ^^^^^^^^^^^^^^^^^^^^^^^^^^^^^^^^^
  File "C:\Users\ahmed\AppData\Local\Programs\Python\Python312\Lib\site-packages\rest_framework\generics.py", line 194, in post
    return self.create(request, *args, **kwargs)
           ^^^^^^^^^^^^^^^^^^^^^^^^^^^^^^^^^^^^^
  File "C:\Users\ahmed\AppData\Local\Programs\Python\Python312\Lib\site-packages\rest_framework\mixins.py", line 19, in create
    self.perform_create(serializer)
  File "A:\web django\GradProject\New folder\BookNest\BookNest\books\views\review_views.py", line 156, in perform_create
    serializer.save(user=self.request.user, book=book)
  File "C:\Users\ahmed\AppData\Local\Programs\Python\Python312\Lib\site-packages\rest_framework\serializers.py", line 208, in save
    self.instance = self.create(validated_data)
                    ^^^^^^^^^^^^^^^^^^^^^^^^^^^
  File "A:\web django\GradProject\New folder\BookNest\BookNest\books\serializers\review_serializers.py", line 83, in create
    book.save()
  File "C:\Users\ahmed\AppData\Local\Programs\Python\Python312\Lib\site-packages\django\db\models\base.py", line 891, in save
    self.save_base(
  File "C:\Users\ahmed\AppData\Local\Programs\Python\Python312\Lib\site-packages\django\db\models\base.py", line 1012, in save_base
    post_save.send(
  File "C:\Users\ahmed\AppData\Local\Programs\Python\Python312\Lib\site-packages\django\dispatch\dispatcher.py", line 189, in send
    response = receiver(signal=self, sender=sender, **named)
               ^^^^^^^^^^^^^^^^^^^^^^^^^^^^^^^^^^^^^^^^^^^^^
  File "C:\Users\ahmed\AppData\Local\Programs\Python\Python312\Lib\site-packages\django_elasticsearch_dsl\signals.py", line 61, in handle_save
    registry.update(instance)
  File "C:\Users\ahmed\AppData\Local\Programs\Python\Python312\Lib\site-packages\django_elasticsearch_dsl\registries.py", line 141, in update
    doc().update(instance, **kwargs)
  File "C:\Users\ahmed\AppData\Local\Programs\Python\Python312\Lib\site-packages\django_elasticsearch_dsl\documents.py", line 259, in update
    return self._bulk(
           ^^^^^^^^^^^
  File "C:\Users\ahmed\AppData\Local\Programs\Python\Python312\Lib\site-packages\django_elasticsearch_dsl\documents.py", line 236, in _bulk
    return self.bulk(*args, **kwargs)
           ^^^^^^^^^^^^^^^^^^^^^^^^^^
  File "C:\Users\ahmed\AppData\Local\Programs\Python\Python312\Lib\site-packages\django_elasticsearch_dsl\documents.py", line 178, in bulk
    response = bulk(client=self._get_connection(), actions=actions, **kwargs)
               ^^^^^^^^^^^^^^^^^^^^^^^^^^^^^^^^^^^^^^^^^^^^^^^^^^^^^^^^^^^^^^
  File "C:\Users\ahmed\AppData\Local\Programs\Python\Python312\Lib\site-packages\elasticsearch\helpers\actions.py", line 410, in bulk
    for ok, item in streaming_bulk(
  File "C:\Users\ahmed\AppData\Local\Programs\Python\Python312\Lib\site-packages\elasticsearch\helpers\actions.py", line 329, in streaming_bulk
    for data, (ok, info) in zip(
  File "C:\Users\ahmed\AppData\Local\Programs\Python\Python312\Lib\site-packages\elasticsearch\helpers\actions.py", line 256, in _process_bulk_chunk
    for item in gen:
  File "C:\Users\ahmed\AppData\Local\Programs\Python\Python312\Lib\site-packages\elasticsearch\helpers\actions.py", line 195, in _process_bulk_chunk_error
    raise error
  File "C:\Users\ahmed\AppData\Local\Programs\Python\Python312\Lib\site-packages\elasticsearch\helpers\actions.py", line 240, in _process_bulk_chunk
    resp = client.bulk(*args, body="\n".join(bulk_actions) + "\n", **kwargs)
           ^^^^^^^^^^^^^^^^^^^^^^^^^^^^^^^^^^^^^^^^^^^^^^^^^^^^^^^^^^^^^^^^^
  File "C:\Users\ahmed\AppData\Local\Programs\Python\Python312\Lib\site-packages\elasticsearch\client\utils.py", line 347, in _wrapped
    return func(*args, params=params, headers=headers, **kwargs)
           ^^^^^^^^^^^^^^^^^^^^^^^^^^^^^^^^^^^^^^^^^^^^^^^^^^^^^
  File "C:\Users\ahmed\AppData\Local\Programs\Python\Python312\Lib\site-packages\elasticsearch\client\__init__.py", line 472, in bulk
    return self.transport.perform_request(
           ^^^^^^^^^^^^^^^^^^^^^^^^^^^^^^^
  File "C:\Users\ahmed\AppData\Local\Programs\Python\Python312\Lib\site-packages\elasticsearch\transport.py", line 417, in perform_request
    self._do_verify_elasticsearch(headers=headers, timeout=timeout)
  File "C:\Users\ahmed\AppData\Local\Programs\Python\Python312\Lib\site-packages\elasticsearch\transport.py", line 606, in _do_verify_elasticsearch
    raise error
  File "C:\Users\ahmed\AppData\Local\Programs\Python\Python312\Lib\site-packages\elasticsearch\transport.py", line 569, in _do_verify_elasticsearch
    _, info_headers, info_response = conn.perform_request(
                                     ^^^^^^^^^^^^^^^^^^^^^
  File "C:\Users\ahmed\AppData\Local\Programs\Python\Python312\Lib\site-packages\elasticsearch\connection\http_urllib3.py", line 280, in perform_request
    raise ConnectionError("N/A", str(e), e)
elasticsearch.exceptions.ConnectionError: ConnectionError(<urllib3.connection.HTTPConnection object at 0x0000020B4A2489E0>: Failed to establish a new connection: [WinError 10061] No connection could be made because the target machine actively refused it) caused by: NewConnectionError(<urllib3.connection.HTTPConnection object at 0x0000020B4A2489E0>: Failed to establish a new connection: [WinError 10061] No connection could be made because the target machine actively refused it)
ERROR 2025-05-16 19:25:54,030 basehttp 41832 16744 "POST /api/v1/books/rating/create/ HTTP/1.1" 500 336907
ERROR 2025-05-16 19:26:04,519 log 41832 16744 Internal Server Error: /api/v1/books/rating/create/
Traceback (most recent call last):
  File "C:\Users\ahmed\AppData\Local\Programs\Python\Python312\Lib\site-packages\urllib3\connection.py", line 174, in _new_conn
    conn = connection.create_connection(
           ^^^^^^^^^^^^^^^^^^^^^^^^^^^^^
  File "C:\Users\ahmed\AppData\Local\Programs\Python\Python312\Lib\site-packages\urllib3\util\connection.py", line 95, in create_connection
    raise err
  File "C:\Users\ahmed\AppData\Local\Programs\Python\Python312\Lib\site-packages\urllib3\util\connection.py", line 85, in create_connection
    sock.connect(sa)
ConnectionRefusedError: [WinError 10061] No connection could be made because the target machine actively refused it

During handling of the above exception, another exception occurred:

Traceback (most recent call last):
  File "C:\Users\ahmed\AppData\Local\Programs\Python\Python312\Lib\site-packages\elasticsearch\connection\http_urllib3.py", line 255, in perform_request
    response = self.pool.urlopen(
               ^^^^^^^^^^^^^^^^^^
  File "C:\Users\ahmed\AppData\Local\Programs\Python\Python312\Lib\site-packages\urllib3\connectionpool.py", line 802, in urlopen
    retries = retries.increment(
              ^^^^^^^^^^^^^^^^^^
  File "C:\Users\ahmed\AppData\Local\Programs\Python\Python312\Lib\site-packages\urllib3\util\retry.py", line 527, in increment
    raise six.reraise(type(error), error, _stacktrace)
          ^^^^^^^^^^^^^^^^^^^^^^^^^^^^^^^^^^^^^^^^^^^^
  File "C:\Users\ahmed\AppData\Local\Programs\Python\Python312\Lib\site-packages\urllib3\packages\six.py", line 770, in reraise
    raise value
  File "C:\Users\ahmed\AppData\Local\Programs\Python\Python312\Lib\site-packages\urllib3\connectionpool.py", line 716, in urlopen
    httplib_response = self._make_request(
                       ^^^^^^^^^^^^^^^^^^^
  File "C:\Users\ahmed\AppData\Local\Programs\Python\Python312\Lib\site-packages\urllib3\connectionpool.py", line 416, in _make_request
    conn.request(method, url, **httplib_request_kw)
  File "C:\Users\ahmed\AppData\Local\Programs\Python\Python312\Lib\site-packages\urllib3\connection.py", line 244, in request
    super(HTTPConnection, self).request(method, url, body=body, headers=headers)
  File "C:\Users\ahmed\AppData\Local\Programs\Python\Python312\Lib\http\client.py", line 1319, in request
    self._send_request(method, url, body, headers, encode_chunked)
  File "C:\Users\ahmed\AppData\Local\Programs\Python\Python312\Lib\http\client.py", line 1365, in _send_request
    self.endheaders(body, encode_chunked=encode_chunked)
  File "C:\Users\ahmed\AppData\Local\Programs\Python\Python312\Lib\http\client.py", line 1314, in endheaders
    self._send_output(message_body, encode_chunked=encode_chunked)
  File "C:\Users\ahmed\AppData\Local\Programs\Python\Python312\Lib\http\client.py", line 1074, in _send_output
    self.send(msg)
  File "C:\Users\ahmed\AppData\Local\Programs\Python\Python312\Lib\http\client.py", line 1018, in send
    self.connect()
  File "C:\Users\ahmed\AppData\Local\Programs\Python\Python312\Lib\site-packages\urllib3\connection.py", line 205, in connect
    conn = self._new_conn()
           ^^^^^^^^^^^^^^^^
  File "C:\Users\ahmed\AppData\Local\Programs\Python\Python312\Lib\site-packages\urllib3\connection.py", line 186, in _new_conn
    raise NewConnectionError(
urllib3.exceptions.NewConnectionError: <urllib3.connection.HTTPConnection object at 0x0000020B4A3A9AC0>: Failed to establish a new connection: [WinError 10061] No connection could be made because the target machine actively refused it

During handling of the above exception, another exception occurred:

Traceback (most recent call last):
  File "C:\Users\ahmed\AppData\Local\Programs\Python\Python312\Lib\site-packages\django\core\handlers\exception.py", line 55, in inner
    response = get_response(request)
               ^^^^^^^^^^^^^^^^^^^^^
  File "C:\Users\ahmed\AppData\Local\Programs\Python\Python312\Lib\site-packages\django\core\handlers\base.py", line 197, in _get_response
    response = wrapped_callback(request, *callback_args, **callback_kwargs)
               ^^^^^^^^^^^^^^^^^^^^^^^^^^^^^^^^^^^^^^^^^^^^^^^^^^^^^^^^^^^^
  File "C:\Users\ahmed\AppData\Local\Programs\Python\Python312\Lib\site-packages\django\views\decorators\csrf.py", line 65, in _view_wrapper
    return view_func(request, *args, **kwargs)
           ^^^^^^^^^^^^^^^^^^^^^^^^^^^^^^^^^^^
  File "C:\Users\ahmed\AppData\Local\Programs\Python\Python312\Lib\site-packages\django\views\generic\base.py", line 104, in view
    return self.dispatch(request, *args, **kwargs)
           ^^^^^^^^^^^^^^^^^^^^^^^^^^^^^^^^^^^^^^^
  File "C:\Users\ahmed\AppData\Local\Programs\Python\Python312\Lib\site-packages\rest_framework\views.py", line 509, in dispatch
    response = self.handle_exception(exc)
               ^^^^^^^^^^^^^^^^^^^^^^^^^^
  File "C:\Users\ahmed\AppData\Local\Programs\Python\Python312\Lib\site-packages\rest_framework\views.py", line 469, in handle_exception
    self.raise_uncaught_exception(exc)
  File "C:\Users\ahmed\AppData\Local\Programs\Python\Python312\Lib\site-packages\rest_framework\views.py", line 480, in raise_uncaught_exception
    raise exc
  File "C:\Users\ahmed\AppData\Local\Programs\Python\Python312\Lib\site-packages\rest_framework\views.py", line 506, in dispatch
    response = handler(request, *args, **kwargs)
               ^^^^^^^^^^^^^^^^^^^^^^^^^^^^^^^^^
  File "C:\Users\ahmed\AppData\Local\Programs\Python\Python312\Lib\site-packages\rest_framework\generics.py", line 194, in post
    return self.create(request, *args, **kwargs)
           ^^^^^^^^^^^^^^^^^^^^^^^^^^^^^^^^^^^^^
  File "C:\Users\ahmed\AppData\Local\Programs\Python\Python312\Lib\site-packages\rest_framework\mixins.py", line 19, in create
    self.perform_create(serializer)
  File "A:\web django\GradProject\New folder\BookNest\BookNest\books\views\review_views.py", line 156, in perform_create
    serializer.save(user=self.request.user, book=book)
  File "C:\Users\ahmed\AppData\Local\Programs\Python\Python312\Lib\site-packages\rest_framework\serializers.py", line 208, in save
    self.instance = self.create(validated_data)
                    ^^^^^^^^^^^^^^^^^^^^^^^^^^^
  File "A:\web django\GradProject\New folder\BookNest\BookNest\books\serializers\review_serializers.py", line 83, in create
    book.save()
  File "C:\Users\ahmed\AppData\Local\Programs\Python\Python312\Lib\site-packages\django\db\models\base.py", line 891, in save
    self.save_base(
  File "C:\Users\ahmed\AppData\Local\Programs\Python\Python312\Lib\site-packages\django\db\models\base.py", line 1012, in save_base
    post_save.send(
  File "C:\Users\ahmed\AppData\Local\Programs\Python\Python312\Lib\site-packages\django\dispatch\dispatcher.py", line 189, in send
    response = receiver(signal=self, sender=sender, **named)
               ^^^^^^^^^^^^^^^^^^^^^^^^^^^^^^^^^^^^^^^^^^^^^
  File "C:\Users\ahmed\AppData\Local\Programs\Python\Python312\Lib\site-packages\django_elasticsearch_dsl\signals.py", line 61, in handle_save
    registry.update(instance)
  File "C:\Users\ahmed\AppData\Local\Programs\Python\Python312\Lib\site-packages\django_elasticsearch_dsl\registries.py", line 141, in update
    doc().update(instance, **kwargs)
  File "C:\Users\ahmed\AppData\Local\Programs\Python\Python312\Lib\site-packages\django_elasticsearch_dsl\documents.py", line 259, in update
    return self._bulk(
           ^^^^^^^^^^^
  File "C:\Users\ahmed\AppData\Local\Programs\Python\Python312\Lib\site-packages\django_elasticsearch_dsl\documents.py", line 236, in _bulk
    return self.bulk(*args, **kwargs)
           ^^^^^^^^^^^^^^^^^^^^^^^^^^
  File "C:\Users\ahmed\AppData\Local\Programs\Python\Python312\Lib\site-packages\django_elasticsearch_dsl\documents.py", line 178, in bulk
    response = bulk(client=self._get_connection(), actions=actions, **kwargs)
               ^^^^^^^^^^^^^^^^^^^^^^^^^^^^^^^^^^^^^^^^^^^^^^^^^^^^^^^^^^^^^^
  File "C:\Users\ahmed\AppData\Local\Programs\Python\Python312\Lib\site-packages\elasticsearch\helpers\actions.py", line 410, in bulk
    for ok, item in streaming_bulk(
  File "C:\Users\ahmed\AppData\Local\Programs\Python\Python312\Lib\site-packages\elasticsearch\helpers\actions.py", line 329, in streaming_bulk
    for data, (ok, info) in zip(
  File "C:\Users\ahmed\AppData\Local\Programs\Python\Python312\Lib\site-packages\elasticsearch\helpers\actions.py", line 256, in _process_bulk_chunk
    for item in gen:
  File "C:\Users\ahmed\AppData\Local\Programs\Python\Python312\Lib\site-packages\elasticsearch\helpers\actions.py", line 195, in _process_bulk_chunk_error
    raise error
  File "C:\Users\ahmed\AppData\Local\Programs\Python\Python312\Lib\site-packages\elasticsearch\helpers\actions.py", line 240, in _process_bulk_chunk
    resp = client.bulk(*args, body="\n".join(bulk_actions) + "\n", **kwargs)
           ^^^^^^^^^^^^^^^^^^^^^^^^^^^^^^^^^^^^^^^^^^^^^^^^^^^^^^^^^^^^^^^^^
  File "C:\Users\ahmed\AppData\Local\Programs\Python\Python312\Lib\site-packages\elasticsearch\client\utils.py", line 347, in _wrapped
    return func(*args, params=params, headers=headers, **kwargs)
           ^^^^^^^^^^^^^^^^^^^^^^^^^^^^^^^^^^^^^^^^^^^^^^^^^^^^^
  File "C:\Users\ahmed\AppData\Local\Programs\Python\Python312\Lib\site-packages\elasticsearch\client\__init__.py", line 472, in bulk
    return self.transport.perform_request(
           ^^^^^^^^^^^^^^^^^^^^^^^^^^^^^^^
  File "C:\Users\ahmed\AppData\Local\Programs\Python\Python312\Lib\site-packages\elasticsearch\transport.py", line 417, in perform_request
    self._do_verify_elasticsearch(headers=headers, timeout=timeout)
  File "C:\Users\ahmed\AppData\Local\Programs\Python\Python312\Lib\site-packages\elasticsearch\transport.py", line 606, in _do_verify_elasticsearch
    raise error
  File "C:\Users\ahmed\AppData\Local\Programs\Python\Python312\Lib\site-packages\elasticsearch\transport.py", line 569, in _do_verify_elasticsearch
    _, info_headers, info_response = conn.perform_request(
                                     ^^^^^^^^^^^^^^^^^^^^^
  File "C:\Users\ahmed\AppData\Local\Programs\Python\Python312\Lib\site-packages\elasticsearch\connection\http_urllib3.py", line 280, in perform_request
    raise ConnectionError("N/A", str(e), e)
elasticsearch.exceptions.ConnectionError: ConnectionError(<urllib3.connection.HTTPConnection object at 0x0000020B4A3A9AC0>: Failed to establish a new connection: [WinError 10061] No connection could be made because the target machine actively refused it) caused by: NewConnectionError(<urllib3.connection.HTTPConnection object at 0x0000020B4A3A9AC0>: Failed to establish a new connection: [WinError 10061] No connection could be made because the target machine actively refused it)
ERROR 2025-05-16 19:26:04,533 basehttp 41832 16744 "POST /api/v1/books/rating/create/ HTTP/1.1" 500 333811
ERROR 2025-05-16 19:26:16,978 log 41832 16744 Internal Server Error: /api/v1/books/rating/create/
Traceback (most recent call last):
  File "C:\Users\ahmed\AppData\Local\Programs\Python\Python312\Lib\site-packages\urllib3\connection.py", line 174, in _new_conn
    conn = connection.create_connection(
           ^^^^^^^^^^^^^^^^^^^^^^^^^^^^^
  File "C:\Users\ahmed\AppData\Local\Programs\Python\Python312\Lib\site-packages\urllib3\util\connection.py", line 95, in create_connection
    raise err
  File "C:\Users\ahmed\AppData\Local\Programs\Python\Python312\Lib\site-packages\urllib3\util\connection.py", line 85, in create_connection
    sock.connect(sa)
ConnectionRefusedError: [WinError 10061] No connection could be made because the target machine actively refused it

During handling of the above exception, another exception occurred:

Traceback (most recent call last):
  File "C:\Users\ahmed\AppData\Local\Programs\Python\Python312\Lib\site-packages\elasticsearch\connection\http_urllib3.py", line 255, in perform_request
    response = self.pool.urlopen(
               ^^^^^^^^^^^^^^^^^^
  File "C:\Users\ahmed\AppData\Local\Programs\Python\Python312\Lib\site-packages\urllib3\connectionpool.py", line 802, in urlopen
    retries = retries.increment(
              ^^^^^^^^^^^^^^^^^^
  File "C:\Users\ahmed\AppData\Local\Programs\Python\Python312\Lib\site-packages\urllib3\util\retry.py", line 527, in increment
    raise six.reraise(type(error), error, _stacktrace)
          ^^^^^^^^^^^^^^^^^^^^^^^^^^^^^^^^^^^^^^^^^^^^
  File "C:\Users\ahmed\AppData\Local\Programs\Python\Python312\Lib\site-packages\urllib3\packages\six.py", line 770, in reraise
    raise value
  File "C:\Users\ahmed\AppData\Local\Programs\Python\Python312\Lib\site-packages\urllib3\connectionpool.py", line 716, in urlopen
    httplib_response = self._make_request(
                       ^^^^^^^^^^^^^^^^^^^
  File "C:\Users\ahmed\AppData\Local\Programs\Python\Python312\Lib\site-packages\urllib3\connectionpool.py", line 416, in _make_request
    conn.request(method, url, **httplib_request_kw)
  File "C:\Users\ahmed\AppData\Local\Programs\Python\Python312\Lib\site-packages\urllib3\connection.py", line 244, in request
    super(HTTPConnection, self).request(method, url, body=body, headers=headers)
  File "C:\Users\ahmed\AppData\Local\Programs\Python\Python312\Lib\http\client.py", line 1319, in request
    self._send_request(method, url, body, headers, encode_chunked)
  File "C:\Users\ahmed\AppData\Local\Programs\Python\Python312\Lib\http\client.py", line 1365, in _send_request
    self.endheaders(body, encode_chunked=encode_chunked)
  File "C:\Users\ahmed\AppData\Local\Programs\Python\Python312\Lib\http\client.py", line 1314, in endheaders
    self._send_output(message_body, encode_chunked=encode_chunked)
  File "C:\Users\ahmed\AppData\Local\Programs\Python\Python312\Lib\http\client.py", line 1074, in _send_output
    self.send(msg)
  File "C:\Users\ahmed\AppData\Local\Programs\Python\Python312\Lib\http\client.py", line 1018, in send
    self.connect()
  File "C:\Users\ahmed\AppData\Local\Programs\Python\Python312\Lib\site-packages\urllib3\connection.py", line 205, in connect
    conn = self._new_conn()
           ^^^^^^^^^^^^^^^^
  File "C:\Users\ahmed\AppData\Local\Programs\Python\Python312\Lib\site-packages\urllib3\connection.py", line 186, in _new_conn
    raise NewConnectionError(
urllib3.exceptions.NewConnectionError: <urllib3.connection.HTTPConnection object at 0x0000020B4A187230>: Failed to establish a new connection: [WinError 10061] No connection could be made because the target machine actively refused it

During handling of the above exception, another exception occurred:

Traceback (most recent call last):
  File "C:\Users\ahmed\AppData\Local\Programs\Python\Python312\Lib\site-packages\django\core\handlers\exception.py", line 55, in inner
    response = get_response(request)
               ^^^^^^^^^^^^^^^^^^^^^
  File "C:\Users\ahmed\AppData\Local\Programs\Python\Python312\Lib\site-packages\django\core\handlers\base.py", line 197, in _get_response
    response = wrapped_callback(request, *callback_args, **callback_kwargs)
               ^^^^^^^^^^^^^^^^^^^^^^^^^^^^^^^^^^^^^^^^^^^^^^^^^^^^^^^^^^^^
  File "C:\Users\ahmed\AppData\Local\Programs\Python\Python312\Lib\site-packages\django\views\decorators\csrf.py", line 65, in _view_wrapper
    return view_func(request, *args, **kwargs)
           ^^^^^^^^^^^^^^^^^^^^^^^^^^^^^^^^^^^
  File "C:\Users\ahmed\AppData\Local\Programs\Python\Python312\Lib\site-packages\django\views\generic\base.py", line 104, in view
    return self.dispatch(request, *args, **kwargs)
           ^^^^^^^^^^^^^^^^^^^^^^^^^^^^^^^^^^^^^^^
  File "C:\Users\ahmed\AppData\Local\Programs\Python\Python312\Lib\site-packages\rest_framework\views.py", line 509, in dispatch
    response = self.handle_exception(exc)
               ^^^^^^^^^^^^^^^^^^^^^^^^^^
  File "C:\Users\ahmed\AppData\Local\Programs\Python\Python312\Lib\site-packages\rest_framework\views.py", line 469, in handle_exception
    self.raise_uncaught_exception(exc)
  File "C:\Users\ahmed\AppData\Local\Programs\Python\Python312\Lib\site-packages\rest_framework\views.py", line 480, in raise_uncaught_exception
    raise exc
  File "C:\Users\ahmed\AppData\Local\Programs\Python\Python312\Lib\site-packages\rest_framework\views.py", line 506, in dispatch
    response = handler(request, *args, **kwargs)
               ^^^^^^^^^^^^^^^^^^^^^^^^^^^^^^^^^
  File "C:\Users\ahmed\AppData\Local\Programs\Python\Python312\Lib\site-packages\rest_framework\generics.py", line 194, in post
    return self.create(request, *args, **kwargs)
           ^^^^^^^^^^^^^^^^^^^^^^^^^^^^^^^^^^^^^
  File "C:\Users\ahmed\AppData\Local\Programs\Python\Python312\Lib\site-packages\rest_framework\mixins.py", line 19, in create
    self.perform_create(serializer)
  File "A:\web django\GradProject\New folder\BookNest\BookNest\books\views\review_views.py", line 156, in perform_create
    serializer.save(user=self.request.user, book=book)
  File "C:\Users\ahmed\AppData\Local\Programs\Python\Python312\Lib\site-packages\rest_framework\serializers.py", line 208, in save
    self.instance = self.create(validated_data)
                    ^^^^^^^^^^^^^^^^^^^^^^^^^^^
  File "A:\web django\GradProject\New folder\BookNest\BookNest\books\serializers\review_serializers.py", line 83, in create
    book.save()
  File "C:\Users\ahmed\AppData\Local\Programs\Python\Python312\Lib\site-packages\django\db\models\base.py", line 891, in save
    self.save_base(
  File "C:\Users\ahmed\AppData\Local\Programs\Python\Python312\Lib\site-packages\django\db\models\base.py", line 1012, in save_base
    post_save.send(
  File "C:\Users\ahmed\AppData\Local\Programs\Python\Python312\Lib\site-packages\django\dispatch\dispatcher.py", line 189, in send
    response = receiver(signal=self, sender=sender, **named)
               ^^^^^^^^^^^^^^^^^^^^^^^^^^^^^^^^^^^^^^^^^^^^^
  File "C:\Users\ahmed\AppData\Local\Programs\Python\Python312\Lib\site-packages\django_elasticsearch_dsl\signals.py", line 61, in handle_save
    registry.update(instance)
  File "C:\Users\ahmed\AppData\Local\Programs\Python\Python312\Lib\site-packages\django_elasticsearch_dsl\registries.py", line 141, in update
    doc().update(instance, **kwargs)
  File "C:\Users\ahmed\AppData\Local\Programs\Python\Python312\Lib\site-packages\django_elasticsearch_dsl\documents.py", line 259, in update
    return self._bulk(
           ^^^^^^^^^^^
  File "C:\Users\ahmed\AppData\Local\Programs\Python\Python312\Lib\site-packages\django_elasticsearch_dsl\documents.py", line 236, in _bulk
    return self.bulk(*args, **kwargs)
           ^^^^^^^^^^^^^^^^^^^^^^^^^^
  File "C:\Users\ahmed\AppData\Local\Programs\Python\Python312\Lib\site-packages\django_elasticsearch_dsl\documents.py", line 178, in bulk
    response = bulk(client=self._get_connection(), actions=actions, **kwargs)
               ^^^^^^^^^^^^^^^^^^^^^^^^^^^^^^^^^^^^^^^^^^^^^^^^^^^^^^^^^^^^^^
  File "C:\Users\ahmed\AppData\Local\Programs\Python\Python312\Lib\site-packages\elasticsearch\helpers\actions.py", line 410, in bulk
    for ok, item in streaming_bulk(
  File "C:\Users\ahmed\AppData\Local\Programs\Python\Python312\Lib\site-packages\elasticsearch\helpers\actions.py", line 329, in streaming_bulk
    for data, (ok, info) in zip(
  File "C:\Users\ahmed\AppData\Local\Programs\Python\Python312\Lib\site-packages\elasticsearch\helpers\actions.py", line 256, in _process_bulk_chunk
    for item in gen:
  File "C:\Users\ahmed\AppData\Local\Programs\Python\Python312\Lib\site-packages\elasticsearch\helpers\actions.py", line 195, in _process_bulk_chunk_error
    raise error
  File "C:\Users\ahmed\AppData\Local\Programs\Python\Python312\Lib\site-packages\elasticsearch\helpers\actions.py", line 240, in _process_bulk_chunk
    resp = client.bulk(*args, body="\n".join(bulk_actions) + "\n", **kwargs)
           ^^^^^^^^^^^^^^^^^^^^^^^^^^^^^^^^^^^^^^^^^^^^^^^^^^^^^^^^^^^^^^^^^
  File "C:\Users\ahmed\AppData\Local\Programs\Python\Python312\Lib\site-packages\elasticsearch\client\utils.py", line 347, in _wrapped
    return func(*args, params=params, headers=headers, **kwargs)
           ^^^^^^^^^^^^^^^^^^^^^^^^^^^^^^^^^^^^^^^^^^^^^^^^^^^^^
  File "C:\Users\ahmed\AppData\Local\Programs\Python\Python312\Lib\site-packages\elasticsearch\client\__init__.py", line 472, in bulk
    return self.transport.perform_request(
           ^^^^^^^^^^^^^^^^^^^^^^^^^^^^^^^
  File "C:\Users\ahmed\AppData\Local\Programs\Python\Python312\Lib\site-packages\elasticsearch\transport.py", line 417, in perform_request
    self._do_verify_elasticsearch(headers=headers, timeout=timeout)
  File "C:\Users\ahmed\AppData\Local\Programs\Python\Python312\Lib\site-packages\elasticsearch\transport.py", line 606, in _do_verify_elasticsearch
    raise error
  File "C:\Users\ahmed\AppData\Local\Programs\Python\Python312\Lib\site-packages\elasticsearch\transport.py", line 569, in _do_verify_elasticsearch
    _, info_headers, info_response = conn.perform_request(
                                     ^^^^^^^^^^^^^^^^^^^^^
  File "C:\Users\ahmed\AppData\Local\Programs\Python\Python312\Lib\site-packages\elasticsearch\connection\http_urllib3.py", line 280, in perform_request
    raise ConnectionError("N/A", str(e), e)
elasticsearch.exceptions.ConnectionError: ConnectionError(<urllib3.connection.HTTPConnection object at 0x0000020B4A187230>: Failed to establish a new connection: [WinError 10061] No connection could be made because the target machine actively refused it) caused by: NewConnectionError(<urllib3.connection.HTTPConnection object at 0x0000020B4A187230>: Failed to establish a new connection: [WinError 10061] No connection could be made because the target machine actively refused it)
ERROR 2025-05-16 19:26:16,988 basehttp 41832 16744 "POST /api/v1/books/rating/create/ HTTP/1.1" 500 335049
ERROR 2025-05-16 19:29:16,068 log 41832 8532 Internal Server Error: /api/v1/books/rating/create/
Traceback (most recent call last):
  File "C:\Users\ahmed\AppData\Local\Programs\Python\Python312\Lib\site-packages\urllib3\connection.py", line 174, in _new_conn
    conn = connection.create_connection(
           ^^^^^^^^^^^^^^^^^^^^^^^^^^^^^
  File "C:\Users\ahmed\AppData\Local\Programs\Python\Python312\Lib\site-packages\urllib3\util\connection.py", line 95, in create_connection
    raise err
  File "C:\Users\ahmed\AppData\Local\Programs\Python\Python312\Lib\site-packages\urllib3\util\connection.py", line 85, in create_connection
    sock.connect(sa)
ConnectionRefusedError: [WinError 10061] No connection could be made because the target machine actively refused it

During handling of the above exception, another exception occurred:

Traceback (most recent call last):
  File "C:\Users\ahmed\AppData\Local\Programs\Python\Python312\Lib\site-packages\elasticsearch\connection\http_urllib3.py", line 255, in perform_request
    response = self.pool.urlopen(
               ^^^^^^^^^^^^^^^^^^
  File "C:\Users\ahmed\AppData\Local\Programs\Python\Python312\Lib\site-packages\urllib3\connectionpool.py", line 802, in urlopen
    retries = retries.increment(
              ^^^^^^^^^^^^^^^^^^
  File "C:\Users\ahmed\AppData\Local\Programs\Python\Python312\Lib\site-packages\urllib3\util\retry.py", line 527, in increment
    raise six.reraise(type(error), error, _stacktrace)
          ^^^^^^^^^^^^^^^^^^^^^^^^^^^^^^^^^^^^^^^^^^^^
  File "C:\Users\ahmed\AppData\Local\Programs\Python\Python312\Lib\site-packages\urllib3\packages\six.py", line 770, in reraise
    raise value
  File "C:\Users\ahmed\AppData\Local\Programs\Python\Python312\Lib\site-packages\urllib3\connectionpool.py", line 716, in urlopen
    httplib_response = self._make_request(
                       ^^^^^^^^^^^^^^^^^^^
  File "C:\Users\ahmed\AppData\Local\Programs\Python\Python312\Lib\site-packages\urllib3\connectionpool.py", line 416, in _make_request
    conn.request(method, url, **httplib_request_kw)
  File "C:\Users\ahmed\AppData\Local\Programs\Python\Python312\Lib\site-packages\urllib3\connection.py", line 244, in request
    super(HTTPConnection, self).request(method, url, body=body, headers=headers)
  File "C:\Users\ahmed\AppData\Local\Programs\Python\Python312\Lib\http\client.py", line 1319, in request
    self._send_request(method, url, body, headers, encode_chunked)
  File "C:\Users\ahmed\AppData\Local\Programs\Python\Python312\Lib\http\client.py", line 1365, in _send_request
    self.endheaders(body, encode_chunked=encode_chunked)
  File "C:\Users\ahmed\AppData\Local\Programs\Python\Python312\Lib\http\client.py", line 1314, in endheaders
    self._send_output(message_body, encode_chunked=encode_chunked)
  File "C:\Users\ahmed\AppData\Local\Programs\Python\Python312\Lib\http\client.py", line 1074, in _send_output
    self.send(msg)
  File "C:\Users\ahmed\AppData\Local\Programs\Python\Python312\Lib\http\client.py", line 1018, in send
    self.connect()
  File "C:\Users\ahmed\AppData\Local\Programs\Python\Python312\Lib\site-packages\urllib3\connection.py", line 205, in connect
    conn = self._new_conn()
           ^^^^^^^^^^^^^^^^
  File "C:\Users\ahmed\AppData\Local\Programs\Python\Python312\Lib\site-packages\urllib3\connection.py", line 186, in _new_conn
    raise NewConnectionError(
urllib3.exceptions.NewConnectionError: <urllib3.connection.HTTPConnection object at 0x0000020B4A9E6EA0>: Failed to establish a new connection: [WinError 10061] No connection could be made because the target machine actively refused it

During handling of the above exception, another exception occurred:

Traceback (most recent call last):
  File "C:\Users\ahmed\AppData\Local\Programs\Python\Python312\Lib\site-packages\django\core\handlers\exception.py", line 55, in inner
    response = get_response(request)
               ^^^^^^^^^^^^^^^^^^^^^
  File "C:\Users\ahmed\AppData\Local\Programs\Python\Python312\Lib\site-packages\django\core\handlers\base.py", line 197, in _get_response
    response = wrapped_callback(request, *callback_args, **callback_kwargs)
               ^^^^^^^^^^^^^^^^^^^^^^^^^^^^^^^^^^^^^^^^^^^^^^^^^^^^^^^^^^^^
  File "C:\Users\ahmed\AppData\Local\Programs\Python\Python312\Lib\site-packages\django\views\decorators\csrf.py", line 65, in _view_wrapper
    return view_func(request, *args, **kwargs)
           ^^^^^^^^^^^^^^^^^^^^^^^^^^^^^^^^^^^
  File "C:\Users\ahmed\AppData\Local\Programs\Python\Python312\Lib\site-packages\django\views\generic\base.py", line 104, in view
    return self.dispatch(request, *args, **kwargs)
           ^^^^^^^^^^^^^^^^^^^^^^^^^^^^^^^^^^^^^^^
  File "C:\Users\ahmed\AppData\Local\Programs\Python\Python312\Lib\site-packages\rest_framework\views.py", line 509, in dispatch
    response = self.handle_exception(exc)
               ^^^^^^^^^^^^^^^^^^^^^^^^^^
  File "C:\Users\ahmed\AppData\Local\Programs\Python\Python312\Lib\site-packages\rest_framework\views.py", line 469, in handle_exception
    self.raise_uncaught_exception(exc)
  File "C:\Users\ahmed\AppData\Local\Programs\Python\Python312\Lib\site-packages\rest_framework\views.py", line 480, in raise_uncaught_exception
    raise exc
  File "C:\Users\ahmed\AppData\Local\Programs\Python\Python312\Lib\site-packages\rest_framework\views.py", line 506, in dispatch
    response = handler(request, *args, **kwargs)
               ^^^^^^^^^^^^^^^^^^^^^^^^^^^^^^^^^
  File "C:\Users\ahmed\AppData\Local\Programs\Python\Python312\Lib\site-packages\rest_framework\generics.py", line 194, in post
    return self.create(request, *args, **kwargs)
           ^^^^^^^^^^^^^^^^^^^^^^^^^^^^^^^^^^^^^
  File "C:\Users\ahmed\AppData\Local\Programs\Python\Python312\Lib\site-packages\rest_framework\mixins.py", line 19, in create
    self.perform_create(serializer)
  File "A:\web django\GradProject\New folder\BookNest\BookNest\books\views\review_views.py", line 156, in perform_create
    serializer.save(user=self.request.user, book=book)
  File "C:\Users\ahmed\AppData\Local\Programs\Python\Python312\Lib\site-packages\rest_framework\serializers.py", line 208, in save
    self.instance = self.create(validated_data)
                    ^^^^^^^^^^^^^^^^^^^^^^^^^^^
  File "A:\web django\GradProject\New folder\BookNest\BookNest\books\serializers\review_serializers.py", line 83, in create
    book.save()
  File "C:\Users\ahmed\AppData\Local\Programs\Python\Python312\Lib\site-packages\django\db\models\base.py", line 891, in save
    self.save_base(
  File "C:\Users\ahmed\AppData\Local\Programs\Python\Python312\Lib\site-packages\django\db\models\base.py", line 1012, in save_base
    post_save.send(
  File "C:\Users\ahmed\AppData\Local\Programs\Python\Python312\Lib\site-packages\django\dispatch\dispatcher.py", line 189, in send
    response = receiver(signal=self, sender=sender, **named)
               ^^^^^^^^^^^^^^^^^^^^^^^^^^^^^^^^^^^^^^^^^^^^^
  File "C:\Users\ahmed\AppData\Local\Programs\Python\Python312\Lib\site-packages\django_elasticsearch_dsl\signals.py", line 61, in handle_save
    registry.update(instance)
  File "C:\Users\ahmed\AppData\Local\Programs\Python\Python312\Lib\site-packages\django_elasticsearch_dsl\registries.py", line 141, in update
    doc().update(instance, **kwargs)
  File "C:\Users\ahmed\AppData\Local\Programs\Python\Python312\Lib\site-packages\django_elasticsearch_dsl\documents.py", line 259, in update
    return self._bulk(
           ^^^^^^^^^^^
  File "C:\Users\ahmed\AppData\Local\Programs\Python\Python312\Lib\site-packages\django_elasticsearch_dsl\documents.py", line 236, in _bulk
    return self.bulk(*args, **kwargs)
           ^^^^^^^^^^^^^^^^^^^^^^^^^^
  File "C:\Users\ahmed\AppData\Local\Programs\Python\Python312\Lib\site-packages\django_elasticsearch_dsl\documents.py", line 178, in bulk
    response = bulk(client=self._get_connection(), actions=actions, **kwargs)
               ^^^^^^^^^^^^^^^^^^^^^^^^^^^^^^^^^^^^^^^^^^^^^^^^^^^^^^^^^^^^^^
  File "C:\Users\ahmed\AppData\Local\Programs\Python\Python312\Lib\site-packages\elasticsearch\helpers\actions.py", line 410, in bulk
    for ok, item in streaming_bulk(
  File "C:\Users\ahmed\AppData\Local\Programs\Python\Python312\Lib\site-packages\elasticsearch\helpers\actions.py", line 329, in streaming_bulk
    for data, (ok, info) in zip(
  File "C:\Users\ahmed\AppData\Local\Programs\Python\Python312\Lib\site-packages\elasticsearch\helpers\actions.py", line 256, in _process_bulk_chunk
    for item in gen:
  File "C:\Users\ahmed\AppData\Local\Programs\Python\Python312\Lib\site-packages\elasticsearch\helpers\actions.py", line 195, in _process_bulk_chunk_error
    raise error
  File "C:\Users\ahmed\AppData\Local\Programs\Python\Python312\Lib\site-packages\elasticsearch\helpers\actions.py", line 240, in _process_bulk_chunk
    resp = client.bulk(*args, body="\n".join(bulk_actions) + "\n", **kwargs)
           ^^^^^^^^^^^^^^^^^^^^^^^^^^^^^^^^^^^^^^^^^^^^^^^^^^^^^^^^^^^^^^^^^
  File "C:\Users\ahmed\AppData\Local\Programs\Python\Python312\Lib\site-packages\elasticsearch\client\utils.py", line 347, in _wrapped
    return func(*args, params=params, headers=headers, **kwargs)
           ^^^^^^^^^^^^^^^^^^^^^^^^^^^^^^^^^^^^^^^^^^^^^^^^^^^^^
  File "C:\Users\ahmed\AppData\Local\Programs\Python\Python312\Lib\site-packages\elasticsearch\client\__init__.py", line 472, in bulk
    return self.transport.perform_request(
           ^^^^^^^^^^^^^^^^^^^^^^^^^^^^^^^
  File "C:\Users\ahmed\AppData\Local\Programs\Python\Python312\Lib\site-packages\elasticsearch\transport.py", line 417, in perform_request
    self._do_verify_elasticsearch(headers=headers, timeout=timeout)
  File "C:\Users\ahmed\AppData\Local\Programs\Python\Python312\Lib\site-packages\elasticsearch\transport.py", line 606, in _do_verify_elasticsearch
    raise error
  File "C:\Users\ahmed\AppData\Local\Programs\Python\Python312\Lib\site-packages\elasticsearch\transport.py", line 569, in _do_verify_elasticsearch
    _, info_headers, info_response = conn.perform_request(
                                     ^^^^^^^^^^^^^^^^^^^^^
  File "C:\Users\ahmed\AppData\Local\Programs\Python\Python312\Lib\site-packages\elasticsearch\connection\http_urllib3.py", line 280, in perform_request
    raise ConnectionError("N/A", str(e), e)
elasticsearch.exceptions.ConnectionError: ConnectionError(<urllib3.connection.HTTPConnection object at 0x0000020B4A9E6EA0>: Failed to establish a new connection: [WinError 10061] No connection could be made because the target machine actively refused it) caused by: NewConnectionError(<urllib3.connection.HTTPConnection object at 0x0000020B4A9E6EA0>: Failed to establish a new connection: [WinError 10061] No connection could be made because the target machine actively refused it)
ERROR 2025-05-16 19:29:16,081 basehttp 41832 8532 "POST /api/v1/books/rating/create/ HTTP/1.1" 500 329219
INFO 2025-05-16 19:30:29,215 autoreload 41832 6552 A:\web django\GradProject\New folder\BookNest\BookNest\recommendation\apps.py changed, reloading.
INFO 2025-05-16 19:30:32,961 autoreload 36508 42092 Watching for file changes with StatReloader
WARNING 2025-05-16 19:32:02,604 log 36508 42072 Bad Request: /api/v1/books/rating/create/
WARNING 2025-05-16 19:32:02,605 basehttp 36508 42072 "POST /api/v1/books/rating/create/ HTTP/1.1" 400 70
WARNING 2025-05-16 19:32:37,021 log 36508 42072 Bad Request: /api/v1/books/rating/create/
WARNING 2025-05-16 19:32:37,022 basehttp 36508 42072 "POST /api/v1/books/rating/create/ HTTP/1.1" 400 66
WARNING 2025-05-16 19:36:39,321 log 36508 9304 Bad Request: /api/v1/books/rating/create/
WARNING 2025-05-16 19:36:39,323 basehttp 36508 9304 "POST /api/v1/books/rating/create/ HTTP/1.1" 400 66
INFO 2025-05-16 19:36:53,204 basehttp 36508 9304 "POST /api/v1/books/rating/create/ HTTP/1.1" 201 201
WARNING 2025-05-16 19:42:49,865 log 36508 15144 Not Found: /api/auth/login/
WARNING 2025-05-16 19:42:49,866 basehttp 36508 15144 "POST /api/auth/login/ HTTP/1.1" 404 3688
INFO 2025-05-16 19:48:20,566 autoreload 36508 42092 A:\web django\GradProject\New folder\BookNest\BookNest\books\views\review_views.py changed, reloading.
INFO 2025-05-16 19:48:30,257 autoreload 39640 40816 Watching for file changes with StatReloader
INFO 2025-05-16 19:49:02,190 autoreload 39640 40816 A:\web django\GradProject\New folder\BookNest\BookNest\books\urls.py changed, reloading.
INFO 2025-05-16 19:49:07,516 autoreload 22220 26440 Watching for file changes with StatReloader
INFO 2025-05-16 19:49:43,829 autoreload 22220 26440 A:\web django\GradProject\New folder\BookNest\BookNest\books\urls.py changed, reloading.
INFO 2025-05-16 19:49:49,456 autoreload 42316 37188 Watching for file changes with StatReloader
INFO 2025-05-16 19:51:16,591 autoreload 42316 37188 A:\web django\GradProject\New folder\BookNest\BookNest\books\urls.py changed, reloading.
INFO 2025-05-16 19:51:22,471 autoreload 41368 37876 Watching for file changes with StatReloader
WARNING 2025-05-16 19:53:08,892 log 41368 17772 Bad Request: /api/v1/users/login/
WARNING 2025-05-16 19:53:08,893 basehttp 41368 17772 "POST /api/v1/users/login/ HTTP/1.1" 400 37
WARNING 2025-05-16 19:53:30,982 log 41368 12420 Bad Request: /api/v1/users/login/
WARNING 2025-05-16 19:53:30,983 basehttp 41368 12420 "POST /api/v1/users/login/ HTTP/1.1" 400 37
INFO 2025-05-16 19:54:19,788 basehttp 41368 34408 "POST /api/v1/users/login/ HTTP/1.1" 200 671
WARNING 2025-05-16 19:54:19,825 log 41368 34408 Not Found: /api/v1/books/
WARNING 2025-05-16 19:54:19,829 basehttp 41368 34408 "GET /api/v1/books/ HTTP/1.1" 404 13601
INFO 2025-05-16 19:54:51,230 basehttp 41368 38040 "POST /api/v1/users/login/ HTTP/1.1" 200 671
INFO 2025-05-16 19:54:51,238 basehttp 41368 38040 "GET /api/v1/books/list?limit=500 HTTP/1.1" 301 0
WARNING 2025-05-16 19:54:53,286 log 41368 13124 Unauthorized: /api/v1/books/list/
WARNING 2025-05-16 19:54:53,287 basehttp 41368 13124 "GET /api/v1/books/list/?limit=500 HTTP/1.1" 401 58
INFO 2025-05-16 19:58:06,648 autoreload 41368 37876 A:\web django\GradProject\New folder\BookNest\BookNest\recommendation\utils.py changed, reloading.
INFO 2025-05-16 19:58:10,392 autoreload 40852 12412 Watching for file changes with StatReloader
INFO 2025-05-16 20:11:44,023 autoreload 16864 17112 Watching for file changes with StatReloader
INFO 2025-05-16 20:12:06,003 basehttp 16864 7028 "POST /api/v1/books/rating/create/ HTTP/1.1" 201 183
INFO 2025-05-16 20:13:33,282 autoreload 16864 17112 A:\web django\GradProject\New folder\BookNest\BookNest\BookNest\settings.py changed, reloading.
INFO 2025-05-16 20:13:35,992 autoreload 20248 14048 Watching for file changes with StatReloader
INFO 2025-05-16 20:13:42,162 autoreload 20248 14048 A:\web django\GradProject\New folder\BookNest\BookNest\BookNest\settings.py changed, reloading.
INFO 2025-05-16 20:13:45,487 autoreload 22736 28760 Watching for file changes with StatReloader
INFO 2025-05-16 20:13:52,967 basehttp 22736 41156 "GET /api/v1/books/list?limit=500 HTTP/1.1" 301 0
INFO 2025-05-16 20:13:54,883 basehttp 22736 33548 "GET /api/v1/books/list/?limit=500 HTTP/1.1" 200 601366
INFO 2025-05-16 20:14:05,240 basehttp 22736 21800 "POST /api/v1/books/rating/create/ HTTP/1.1" 201 184
INFO 2025-05-16 20:15:36,861 autoreload 22736 28760 A:\web django\GradProject\New folder\BookNest\BookNest\recommendation\apps.py changed, reloading.
INFO 2025-05-16 20:15:39,688 autoreload 24528 17316 Watching for file changes with StatReloader
INFO 2025-05-16 20:16:08,357 autoreload 24528 17316 A:\web django\GradProject\New folder\BookNest\BookNest\recommendation\apps.py changed, reloading.
INFO 2025-05-16 20:16:11,498 autoreload 4728 19272 Watching for file changes with StatReloader
INFO 2025-05-16 20:16:26,293 basehttp 4728 17316 "POST /api/v1/books/rating/create/ HTTP/1.1" 201 204
INFO 2025-05-16 20:16:39,916 basehttp 4728 33240 "GET /api/v1/recommendation/user-recommendations/ HTTP/1.1" 200 2
INFO 2025-05-16 20:16:54,946 basehttp 4728 17316 "POST /api/v1/books/rating/create/ HTTP/1.1" 201 217
INFO 2025-05-16 20:17:05,500 basehttp 4728 17316 "POST /api/v1/books/rating/create/ HTTP/1.1" 201 214
INFO 2025-05-16 20:18:24,487 autoreload 21228 15780 Watching for file changes with StatReloader
WARNING 2025-05-16 20:20:21,085 log 21228 13548 Unauthorized: /api/v1/books/users/15/ratings/
WARNING 2025-05-16 20:20:21,086 basehttp 21228 13548 "GET /api/v1/books/users/15/ratings/ HTTP/1.1" 401 58
INFO 2025-05-16 20:20:36,794 basehttp 21228 13548 "GET /api/v1/books/users/15/ratings/ HTTP/1.1" 200 3284
INFO 2025-05-16 20:21:03,075 autoreload 21228 15780 A:\web django\GradProject\New folder\BookNest\BookNest\recommendation\signals.py changed, reloading.
INFO 2025-05-16 20:21:06,953 autoreload 14128 35904 Watching for file changes with StatReloader
INFO 2025-05-16 20:21:22,849 basehttp 14128 16172 "POST /api/v1/books/rating/create/ HTTP/1.1" 201 192
INFO 2025-05-16 20:21:35,200 basehttp 14128 16172 "POST /api/v1/books/rating/create/ HTTP/1.1" 201 245
INFO 2025-05-16 20:21:57,189 basehttp 14128 16172 "POST /api/v1/books/rating/create/ HTTP/1.1" 201 223
INFO 2025-05-16 20:22:03,922 basehttp 14128 16172 "GET /api/v1/books/users/15/ratings/ HTTP/1.1" 200 3947
INFO 2025-05-16 20:22:09,330 basehttp 14128 16172 "GET /api/v1/books/users/15/ratings/ HTTP/1.1" 200 3947
INFO 2025-05-16 20:22:23,361 basehttp 14128 16172 "POST /api/v1/books/rating/create/ HTTP/1.1" 201 183
INFO 2025-05-16 20:25:11,210 autoreload 14128 35904 A:\web django\GradProject\New folder\BookNest\BookNest\recommendation\signals.py changed, reloading.
INFO 2025-05-16 20:25:15,127 autoreload 33804 37472 Watching for file changes with StatReloader
INFO 2025-05-16 20:25:19,960 autoreload 33804 37472 A:\web django\GradProject\New folder\BookNest\BookNest\recommendation\signals.py changed, reloading.
INFO 2025-05-16 20:25:24,313 autoreload 35616 20044 Watching for file changes with StatReloader
WARNING 2025-05-16 20:25:28,593 log 35616 40772 Unauthorized: /api/v1/books/rating/create/
WARNING 2025-05-16 20:25:28,594 basehttp 35616 40772 "POST /api/v1/books/rating/create/ HTTP/1.1" 401 172
WARNING 2025-05-16 20:25:41,142 log 35616 40772 Unauthorized: /api/v1/books/rating/create/
WARNING 2025-05-16 20:25:41,143 basehttp 35616 40772 "POST /api/v1/books/rating/create/ HTTP/1.1" 401 172
WARNING 2025-05-16 20:25:44,111 log 35616 39548 Bad Request: /api/v1/users/register/
WARNING 2025-05-16 20:25:44,112 basehttp 35616 39548 "POST /api/v1/users/register/ HTTP/1.1" 400 58
INFO 2025-05-16 20:25:51,265 basehttp 35616 39548 "POST /api/v1/users/login/ HTTP/1.1" 200 679
INFO 2025-05-16 20:26:00,336 basehttp 35616 40772 "POST /api/v1/books/rating/create/ HTTP/1.1" 201 182
INFO 2025-05-17 18:54:57,804 autoreload 37772 43312 Watching for file changes with StatReloader
INFO 2025-05-17 18:55:14,398 basehttp 37772 15292 "GET /api/v1/books/list?limit=500 HTTP/1.1" 301 0
WARNING 2025-05-17 18:55:14,966 log 37772 43528 Unauthorized: /api/v1/books/list/
WARNING 2025-05-17 18:55:14,969 basehttp 37772 43528 "GET /api/v1/books/list/?limit=500 HTTP/1.1" 401 172
INFO 2025-05-17 18:55:22,677 basehttp 37772 43528 "POST /api/v1/users/login/ HTTP/1.1" 200 679
INFO 2025-05-17 18:55:25,121 basehttp 37772 43528 "GET /api/v1/books/list?limit=500 HTTP/1.1" 301 0
INFO 2025-05-17 18:55:27,173 basehttp 37772 49544 "GET /api/v1/books/list/?limit=500 HTTP/1.1" 200 605040
ERROR 2025-05-17 18:55:58,712 log 37772 49240 Internal Server Error: /api/v1/books/rating/create/
Traceback (most recent call last):
  File "C:\Users\ahmed\AppData\Local\Programs\Python\Python312\Lib\site-packages\urllib3\connection.py", line 174, in _new_conn
    conn = connection.create_connection(
           ^^^^^^^^^^^^^^^^^^^^^^^^^^^^^
  File "C:\Users\ahmed\AppData\Local\Programs\Python\Python312\Lib\site-packages\urllib3\util\connection.py", line 95, in create_connection
    raise err
  File "C:\Users\ahmed\AppData\Local\Programs\Python\Python312\Lib\site-packages\urllib3\util\connection.py", line 85, in create_connection
    sock.connect(sa)
ConnectionRefusedError: [WinError 10061] No connection could be made because the target machine actively refused it

During handling of the above exception, another exception occurred:

Traceback (most recent call last):
  File "C:\Users\ahmed\AppData\Local\Programs\Python\Python312\Lib\site-packages\elasticsearch\connection\http_urllib3.py", line 255, in perform_request
    response = self.pool.urlopen(
               ^^^^^^^^^^^^^^^^^^
  File "C:\Users\ahmed\AppData\Local\Programs\Python\Python312\Lib\site-packages\urllib3\connectionpool.py", line 802, in urlopen
    retries = retries.increment(
              ^^^^^^^^^^^^^^^^^^
  File "C:\Users\ahmed\AppData\Local\Programs\Python\Python312\Lib\site-packages\urllib3\util\retry.py", line 527, in increment
    raise six.reraise(type(error), error, _stacktrace)
          ^^^^^^^^^^^^^^^^^^^^^^^^^^^^^^^^^^^^^^^^^^^^
  File "C:\Users\ahmed\AppData\Local\Programs\Python\Python312\Lib\site-packages\urllib3\packages\six.py", line 770, in reraise
    raise value
  File "C:\Users\ahmed\AppData\Local\Programs\Python\Python312\Lib\site-packages\urllib3\connectionpool.py", line 716, in urlopen
    httplib_response = self._make_request(
                       ^^^^^^^^^^^^^^^^^^^
  File "C:\Users\ahmed\AppData\Local\Programs\Python\Python312\Lib\site-packages\urllib3\connectionpool.py", line 416, in _make_request
    conn.request(method, url, **httplib_request_kw)
  File "C:\Users\ahmed\AppData\Local\Programs\Python\Python312\Lib\site-packages\urllib3\connection.py", line 244, in request
    super(HTTPConnection, self).request(method, url, body=body, headers=headers)
  File "C:\Users\ahmed\AppData\Local\Programs\Python\Python312\Lib\http\client.py", line 1319, in request
    self._send_request(method, url, body, headers, encode_chunked)
  File "C:\Users\ahmed\AppData\Local\Programs\Python\Python312\Lib\http\client.py", line 1365, in _send_request
    self.endheaders(body, encode_chunked=encode_chunked)
  File "C:\Users\ahmed\AppData\Local\Programs\Python\Python312\Lib\http\client.py", line 1314, in endheaders
    self._send_output(message_body, encode_chunked=encode_chunked)
  File "C:\Users\ahmed\AppData\Local\Programs\Python\Python312\Lib\http\client.py", line 1074, in _send_output
    self.send(msg)
  File "C:\Users\ahmed\AppData\Local\Programs\Python\Python312\Lib\http\client.py", line 1018, in send
    self.connect()
  File "C:\Users\ahmed\AppData\Local\Programs\Python\Python312\Lib\site-packages\urllib3\connection.py", line 205, in connect
    conn = self._new_conn()
           ^^^^^^^^^^^^^^^^
  File "C:\Users\ahmed\AppData\Local\Programs\Python\Python312\Lib\site-packages\urllib3\connection.py", line 186, in _new_conn
    raise NewConnectionError(
urllib3.exceptions.NewConnectionError: <urllib3.connection.HTTPConnection object at 0x0000024CAD48C410>: Failed to establish a new connection: [WinError 10061] No connection could be made because the target machine actively refused it

During handling of the above exception, another exception occurred:

Traceback (most recent call last):
  File "C:\Users\ahmed\AppData\Local\Programs\Python\Python312\Lib\site-packages\django\core\handlers\exception.py", line 55, in inner
    response = get_response(request)
               ^^^^^^^^^^^^^^^^^^^^^
  File "C:\Users\ahmed\AppData\Local\Programs\Python\Python312\Lib\site-packages\django\core\handlers\base.py", line 197, in _get_response
    response = wrapped_callback(request, *callback_args, **callback_kwargs)
               ^^^^^^^^^^^^^^^^^^^^^^^^^^^^^^^^^^^^^^^^^^^^^^^^^^^^^^^^^^^^
  File "C:\Users\ahmed\AppData\Local\Programs\Python\Python312\Lib\site-packages\django\views\decorators\csrf.py", line 65, in _view_wrapper
    return view_func(request, *args, **kwargs)
           ^^^^^^^^^^^^^^^^^^^^^^^^^^^^^^^^^^^
  File "C:\Users\ahmed\AppData\Local\Programs\Python\Python312\Lib\site-packages\django\views\generic\base.py", line 104, in view
    return self.dispatch(request, *args, **kwargs)
           ^^^^^^^^^^^^^^^^^^^^^^^^^^^^^^^^^^^^^^^
  File "C:\Users\ahmed\AppData\Local\Programs\Python\Python312\Lib\site-packages\rest_framework\views.py", line 509, in dispatch
    response = self.handle_exception(exc)
               ^^^^^^^^^^^^^^^^^^^^^^^^^^
  File "C:\Users\ahmed\AppData\Local\Programs\Python\Python312\Lib\site-packages\rest_framework\views.py", line 469, in handle_exception
    self.raise_uncaught_exception(exc)
  File "C:\Users\ahmed\AppData\Local\Programs\Python\Python312\Lib\site-packages\rest_framework\views.py", line 480, in raise_uncaught_exception
    raise exc
  File "C:\Users\ahmed\AppData\Local\Programs\Python\Python312\Lib\site-packages\rest_framework\views.py", line 506, in dispatch
    response = handler(request, *args, **kwargs)
               ^^^^^^^^^^^^^^^^^^^^^^^^^^^^^^^^^
  File "C:\Users\ahmed\AppData\Local\Programs\Python\Python312\Lib\site-packages\rest_framework\generics.py", line 194, in post
    return self.create(request, *args, **kwargs)
           ^^^^^^^^^^^^^^^^^^^^^^^^^^^^^^^^^^^^^
  File "C:\Users\ahmed\AppData\Local\Programs\Python\Python312\Lib\site-packages\rest_framework\mixins.py", line 19, in create
    self.perform_create(serializer)
  File "A:\web django\GradProject\New folder\BookNest\BookNest\books\views\review_views.py", line 157, in perform_create
    serializer.save(user=self.request.user, book=book)
  File "C:\Users\ahmed\AppData\Local\Programs\Python\Python312\Lib\site-packages\rest_framework\serializers.py", line 208, in save
    self.instance = self.create(validated_data)
                    ^^^^^^^^^^^^^^^^^^^^^^^^^^^
  File "A:\web django\GradProject\New folder\BookNest\BookNest\books\serializers\review_serializers.py", line 83, in create
    book.save()
  File "C:\Users\ahmed\AppData\Local\Programs\Python\Python312\Lib\site-packages\django\db\models\base.py", line 891, in save
    self.save_base(
  File "C:\Users\ahmed\AppData\Local\Programs\Python\Python312\Lib\site-packages\django\db\models\base.py", line 1012, in save_base
    post_save.send(
  File "C:\Users\ahmed\AppData\Local\Programs\Python\Python312\Lib\site-packages\django\dispatch\dispatcher.py", line 189, in send
    response = receiver(signal=self, sender=sender, **named)
               ^^^^^^^^^^^^^^^^^^^^^^^^^^^^^^^^^^^^^^^^^^^^^
  File "C:\Users\ahmed\AppData\Local\Programs\Python\Python312\Lib\site-packages\django_elasticsearch_dsl\signals.py", line 61, in handle_save
    registry.update(instance)
  File "C:\Users\ahmed\AppData\Local\Programs\Python\Python312\Lib\site-packages\django_elasticsearch_dsl\registries.py", line 141, in update
    doc().update(instance, **kwargs)
  File "C:\Users\ahmed\AppData\Local\Programs\Python\Python312\Lib\site-packages\django_elasticsearch_dsl\documents.py", line 259, in update
    return self._bulk(
           ^^^^^^^^^^^
  File "C:\Users\ahmed\AppData\Local\Programs\Python\Python312\Lib\site-packages\django_elasticsearch_dsl\documents.py", line 236, in _bulk
    return self.bulk(*args, **kwargs)
           ^^^^^^^^^^^^^^^^^^^^^^^^^^
  File "C:\Users\ahmed\AppData\Local\Programs\Python\Python312\Lib\site-packages\django_elasticsearch_dsl\documents.py", line 178, in bulk
    response = bulk(client=self._get_connection(), actions=actions, **kwargs)
               ^^^^^^^^^^^^^^^^^^^^^^^^^^^^^^^^^^^^^^^^^^^^^^^^^^^^^^^^^^^^^^
  File "C:\Users\ahmed\AppData\Local\Programs\Python\Python312\Lib\site-packages\elasticsearch\helpers\actions.py", line 410, in bulk
    for ok, item in streaming_bulk(
  File "C:\Users\ahmed\AppData\Local\Programs\Python\Python312\Lib\site-packages\elasticsearch\helpers\actions.py", line 329, in streaming_bulk
    for data, (ok, info) in zip(
  File "C:\Users\ahmed\AppData\Local\Programs\Python\Python312\Lib\site-packages\elasticsearch\helpers\actions.py", line 256, in _process_bulk_chunk
    for item in gen:
  File "C:\Users\ahmed\AppData\Local\Programs\Python\Python312\Lib\site-packages\elasticsearch\helpers\actions.py", line 195, in _process_bulk_chunk_error
    raise error
  File "C:\Users\ahmed\AppData\Local\Programs\Python\Python312\Lib\site-packages\elasticsearch\helpers\actions.py", line 240, in _process_bulk_chunk
    resp = client.bulk(*args, body="\n".join(bulk_actions) + "\n", **kwargs)
           ^^^^^^^^^^^^^^^^^^^^^^^^^^^^^^^^^^^^^^^^^^^^^^^^^^^^^^^^^^^^^^^^^
  File "C:\Users\ahmed\AppData\Local\Programs\Python\Python312\Lib\site-packages\elasticsearch\client\utils.py", line 347, in _wrapped
    return func(*args, params=params, headers=headers, **kwargs)
           ^^^^^^^^^^^^^^^^^^^^^^^^^^^^^^^^^^^^^^^^^^^^^^^^^^^^^
  File "C:\Users\ahmed\AppData\Local\Programs\Python\Python312\Lib\site-packages\elasticsearch\client\__init__.py", line 472, in bulk
    return self.transport.perform_request(
           ^^^^^^^^^^^^^^^^^^^^^^^^^^^^^^^
  File "C:\Users\ahmed\AppData\Local\Programs\Python\Python312\Lib\site-packages\elasticsearch\transport.py", line 417, in perform_request
    self._do_verify_elasticsearch(headers=headers, timeout=timeout)
  File "C:\Users\ahmed\AppData\Local\Programs\Python\Python312\Lib\site-packages\elasticsearch\transport.py", line 606, in _do_verify_elasticsearch
    raise error
  File "C:\Users\ahmed\AppData\Local\Programs\Python\Python312\Lib\site-packages\elasticsearch\transport.py", line 569, in _do_verify_elasticsearch
    _, info_headers, info_response = conn.perform_request(
                                     ^^^^^^^^^^^^^^^^^^^^^
  File "C:\Users\ahmed\AppData\Local\Programs\Python\Python312\Lib\site-packages\elasticsearch\connection\http_urllib3.py", line 280, in perform_request
    raise ConnectionError("N/A", str(e), e)
elasticsearch.exceptions.ConnectionError: ConnectionError(<urllib3.connection.HTTPConnection object at 0x0000024CAD48C410>: Failed to establish a new connection: [WinError 10061] No connection could be made because the target machine actively refused it) caused by: NewConnectionError(<urllib3.connection.HTTPConnection object at 0x0000024CAD48C410>: Failed to establish a new connection: [WinError 10061] No connection could be made because the target machine actively refused it)
ERROR 2025-05-17 18:55:58,730 basehttp 37772 49240 "POST /api/v1/books/rating/create/ HTTP/1.1" 500 332329
INFO 2025-05-17 18:56:15,194 basehttp 37772 49544 "GET /api/v1/recommendation/user-recommendations/ HTTP/1.1" 200 1648
INFO 2025-05-23 15:11:24,725 autoreload 17188 2508 Watching for file changes with StatReloader
INFO 2025-05-23 15:30:47,523 autoreload 34836 14780 Watching for file changes with StatReloader
INFO 2025-05-23 20:41:27,288 autoreload 2076 3172 Watching for file changes with StatReloader
INFO 2025-05-23 20:42:32,741 autoreload 19272 5256 Watching for file changes with StatReloader
INFO 2025-05-23 20:43:26,146 autoreload 19272 5256 C:\Users\moata\Desktop\BookNestV2\BookNest\BookNest\settings.py changed, reloading.
INFO 2025-05-23 20:43:33,785 autoreload 23172 23048 Watching for file changes with StatReloader
INFO 2025-05-23 20:44:01,604 autoreload 24224 11580 Watching for file changes with StatReloader
WARNING 2025-05-23 20:44:05,279 log 24224 12860 Not Found: /
WARNING 2025-05-23 20:44:05,280 basehttp 24224 12860 "GET / HTTP/1.1" 404 3624
WARNING 2025-05-23 20:44:05,675 log 24224 12860 Not Found: /favicon.ico
WARNING 2025-05-23 20:44:05,676 basehttp 24224 12860 "GET /favicon.ico HTTP/1.1" 404 3675
INFO 2025-05-23 20:52:46,888 autoreload 24224 11580 C:\Users\moata\Desktop\BookNestV2\BookNest\BookNest\settings.py changed, reloading.
INFO 2025-05-23 20:52:51,185 autoreload 11260 7732 Watching for file changes with StatReloader
INFO 2025-05-23 20:53:16,441 autoreload 11260 7732 C:\Users\moata\Desktop\BookNestV2\BookNest\BookNest\settings.py changed, reloading.
INFO 2025-05-23 20:53:19,391 autoreload 23892 22552 Watching for file changes with StatReloader
INFO 2025-05-23 21:00:52,885 autoreload 23892 22552 C:\Users\moata\Desktop\BookNestV2\BookNest\books\utils\book_service.py changed, reloading.
INFO 2025-05-23 21:00:56,690 autoreload 11492 9776 Watching for file changes with StatReloader
INFO 2025-05-23 21:04:06,844 autoreload 11492 9776 C:\Users\moata\Desktop\BookNestV2\BookNest\books\models.py changed, reloading.
INFO 2025-05-23 21:04:10,871 autoreload 4928 9092 Watching for file changes with StatReloader
INFO 2025-05-23 21:09:01,781 autoreload 4928 9092 C:\Users\moata\Desktop\BookNestV2\BookNest\recommendation\recommendation_engine.py changed, reloading.
INFO 2025-05-23 21:09:05,484 autoreload 12664 12860 Watching for file changes with StatReloader
INFO 2025-05-23 21:09:26,083 autoreload 12664 12860 C:\Users\moata\Desktop\BookNestV2\BookNest\recommendation\recommendation_engine.py changed, reloading.
INFO 2025-05-23 21:09:29,566 autoreload 15928 20760 Watching for file changes with StatReloader
INFO 2025-05-23 21:10:03,158 autoreload 15928 20760 C:\Users\moata\Desktop\BookNestV2\BookNest\recommendation\recommendation_engine.py changed, reloading.
INFO 2025-05-23 21:10:06,347 autoreload 20624 22672 Watching for file changes with StatReloader
INFO 2025-05-23 22:34:52,672 autoreload 5876 6408 Watching for file changes with StatReloader
WARNING 2025-05-23 22:35:28,717 log 5876 4940 Not Found: /
WARNING 2025-05-23 22:35:28,720 basehttp 5876 4940 "GET /?ide_webview_request_time=1748028928611 HTTP/1.1" 404 3663
WARNING 2025-05-23 22:36:57,581 log 5876 23724 Not Found: /
WARNING 2025-05-23 22:36:57,592 basehttp 5876 23724 "GET /?ide_webview_request_time=1748028928611 HTTP/1.1" 404 3663
WARNING 2025-05-23 22:36:57,638 log 5876 23724 Not Found: /
WARNING 2025-05-23 22:36:57,640 basehttp 5876 23724 "GET /?ide_webview_request_time=1748028928611 HTTP/1.1" 404 3663
INFO 2025-05-23 22:46:32,788 autoreload 5876 6408 C:\Users\moata\Desktop\BookNestV2\BookNest\books\views\search_views.py changed, reloading.
INFO 2025-05-23 22:46:35,048 autoreload 17748 23640 Watching for file changes with StatReloader
WARNING 2025-05-23 22:47:13,279 log 17748 23380 Unauthorized: /api/v1/books/search/
WARNING 2025-05-23 22:47:13,280 basehttp 17748 23380 "GET /api/v1/books/search/?q=python&genres=Programming,Technology&min_rating=4.0&page=1&page_size=20 HTTP/1.1" 401 10275
INFO 2025-05-23 22:47:13,893 basehttp 17748 22332 "GET /static/rest_framework/css/bootstrap-tweaks.css HTTP/1.1" 200 3426
INFO 2025-05-23 22:47:13,898 basehttp 17748 5076 "GET /static/rest_framework/css/default.css HTTP/1.1" 200 1152
INFO 2025-05-23 22:47:13,914 basehttp 17748 22332 "GET /static/rest_framework/js/csrf.js HTTP/1.1" 200 1793
INFO 2025-05-23 22:47:13,944 basehttp 17748 21140 "GET /static/rest_framework/css/prettify.css HTTP/1.1" 200 817
INFO 2025-05-23 22:47:13,954 basehttp 17748 23380 "GET /static/rest_framework/css/bootstrap.min.css HTTP/1.1" 200 121457
INFO 2025-05-23 22:47:13,962 basehttp 17748 4988 "GET /static/rest_framework/js/ajax-form.js HTTP/1.1" 200 3796
INFO 2025-05-23 22:47:13,963 basehttp 17748 21140 "GET /static/rest_framework/js/default.js HTTP/1.1" 200 1268
INFO 2025-05-23 22:47:13,971 basehttp 17748 5076 "GET /static/rest_framework/js/bootstrap.min.js HTTP/1.1" 200 39680
INFO 2025-05-23 22:47:13,994 basehttp 17748 23380 "GET /static/rest_framework/js/load-ajax-form.js HTTP/1.1" 200 59
INFO 2025-05-23 22:47:14,025 basehttp 17748 22332 "GET /static/rest_framework/js/prettify-min.js HTTP/1.1" 200 13632
INFO 2025-05-23 22:47:14,032 basehttp 17748 23380 "GET /static/rest_framework/img/grid.png HTTP/1.1" 200 1458
INFO 2025-05-23 22:47:14,076 basehttp 17748 2208 "GET /static/rest_framework/js/jquery-3.7.1.min.js HTTP/1.1" 200 87533
WARNING 2025-05-23 22:47:45,994 log 17748 15680 Unauthorized: /api/v1/users/token/refresh/
WARNING 2025-05-23 22:47:45,999 basehttp 17748 15680 "POST /api/v1/users/token/refresh/ HTTP/1.1" 401 54
WARNING 2025-05-23 22:47:52,737 log 17748 15680 Unauthorized: /api/v1/users/login/
WARNING 2025-05-23 22:47:52,738 basehttp 17748 15680 "POST /api/v1/users/login/ HTTP/1.1" 401 172
WARNING 2025-05-23 22:48:04,587 log 17748 15680 Unauthorized: /api/v1/users/register/
WARNING 2025-05-23 22:48:04,588 basehttp 17748 15680 "POST /api/v1/users/register/ HTTP/1.1" 401 172
WARNING 2025-05-23 22:48:14,981 log 17748 15680 Unauthorized: /api/v1/users/token/refresh/
WARNING 2025-05-23 22:48:14,982 basehttp 17748 15680 "POST /api/v1/users/token/refresh/ HTTP/1.1" 401 54
WARNING 2025-05-23 22:48:20,409 log 17748 15680 Unauthorized: /api/v1/users/login/
WARNING 2025-05-23 22:48:20,414 basehttp 17748 15680 "POST /api/v1/users/login/ HTTP/1.1" 401 172
WARNING 2025-05-23 22:49:39,393 log 17748 6408 Unauthorized: /api/v1/users/login/
WARNING 2025-05-23 22:49:39,394 basehttp 17748 6408 "POST /api/v1/users/login/ HTTP/1.1" 401 172
WARNING 2025-05-23 22:50:33,345 log 17748 6408 Unauthorized: /api/v1/users/token/refresh/
WARNING 2025-05-23 22:50:33,346 basehttp 17748 6408 "POST /api/v1/users/token/refresh/ HTTP/1.1" 401 54
WARNING 2025-05-23 22:53:14,740 log 17748 17216 Unauthorized: /api/v1/users/login/
WARNING 2025-05-23 22:53:14,741 basehttp 17748 17216 "POST /api/v1/users/login/ HTTP/1.1" 401 172
WARNING 2025-05-23 22:54:24,919 log 17748 16412 Not Found: /api/books/search/
WARNING 2025-05-23 22:54:24,920 basehttp 17748 16412 "GET /api/books/search/?q=python&genres=Programming,Technology&min_rating=4.0&page=1&page_size=20 HTTP/1.1" 404 3783
WARNING 2025-05-23 22:54:59,864 log 17748 16412 Unauthorized: /api/v1/books/search/
WARNING 2025-05-23 22:54:59,867 basehttp 17748 16412 "GET /api/v1/books/search/?q=python&genres=Programming,Technology&min_rating=4.0&page=1&page_size=20 HTTP/1.1" 401 172
WARNING 2025-05-23 22:55:23,310 log 17748 16412 Unauthorized: /api/v1/books/search/
WARNING 2025-05-23 22:55:23,319 basehttp 17748 16412 "GET /api/v1/books/search/?q=python&genres=Programming,Technology&min_rating=4.0&page=1&page_size=20 HTTP/1.1" 401 172
WARNING 2025-05-23 22:57:00,356 log 17748 23384 Unauthorized: /api/v1/users/register/
WARNING 2025-05-23 22:57:00,361 basehttp 17748 23384 "POST /api/v1/users/register/ HTTP/1.1" 401 172
WARNING 2025-05-23 22:59:49,955 log 17748 1336 Unauthorized: /api/v1/users/token/refresh/
WARNING 2025-05-23 22:59:49,957 basehttp 17748 1336 "POST /api/v1/users/token/refresh/ HTTP/1.1" 401 54
INFO 2025-05-23 23:00:40,797 basehttp 17748 1336 "POST /api/v1/users/login/ HTTP/1.1" 200 659
INFO 2025-05-23 23:00:44,373 basehttp 17748 1336 "POST /api/v1/users/login/ HTTP/1.1" 200 659
INFO 2025-05-23 23:01:26,039 basehttp 17748 1336 "GET /api/v1/books/search/?q=python&genres=Programming,Technology&min_rating=4.0&page=1&page_size=20 HTTP/1.1" 200 17877
INFO 2025-05-23 23:06:29,168 basehttp 17748 21576 "GET /api/v1/books/search/?q=python&genres=Programming,Technology&min_rating=4.0&page=1&page_size=4 HTTP/1.1" 200 2350
INFO 2025-05-23 23:07:35,388 basehttp 17748 24632 "GET /api/v1/books/search/?q=python&genres=Programming,Technology&min_rating=4.0&page_size=4&page=2 HTTP/1.1" 200 2606
INFO 2025-05-23 23:11:52,377 autoreload 17748 23640 C:\Users\moata\Desktop\BookNestV2\BookNest\books\utils\search_service.py changed, reloading.
INFO 2025-05-23 23:11:55,228 autoreload 660 2424 Watching for file changes with StatReloader
INFO 2025-05-23 23:12:33,636 basehttp 660 2456 "GET /api/v1/books/search/?q=python&genres=Programming,Technology&min_rating=4.0&page_size=4&page=2 HTTP/1.1" 200 2606
INFO 2025-05-23 23:15:07,633 basehttp 660 20704 "GET /api/v1/books/search/?min_rating=4.0&q=harry&page=1&page_size=20&genres=Fantasy HTTP/1.1" 200 511
INFO 2025-05-23 23:16:11,404 autoreload 660 2424 C:\Users\moata\Desktop\BookNestV2\BookNest\books\utils\search_service.py changed, reloading.
INFO 2025-05-23 23:16:14,086 autoreload 25392 5324 Watching for file changes with StatReloader
INFO 2025-05-23 23:16:40,135 autoreload 25392 5324 C:\Users\moata\Desktop\BookNestV2\BookNest\recommendation\recommendation_engine.py changed, reloading.
INFO 2025-05-23 23:16:43,290 autoreload 16024 24432 Watching for file changes with StatReloader
INFO 2025-05-23 23:17:00,669 autoreload 16024 24432 C:\Users\moata\Desktop\BookNestV2\BookNest\recommendation\recommendation_engine.py changed, reloading.
INFO 2025-05-23 23:17:03,502 autoreload 2624 16664 Watching for file changes with StatReloader
INFO 2025-05-23 23:17:43,043 basehttp 2624 24016 "GET /api/v1/books/search/?min_rating=4.0&page=1&page_size=20&genres=Fantasy&q=fantastic HTTP/1.1" 200 19273
INFO 2025-05-23 23:20:51,478 basehttp 2624 8096 "GET /api/v1/books/suggestions/?q=pyth&limit=10 HTTP/1.1" 200 679
INFO 2025-05-23 23:22:52,770 basehttp 2624 13516 "GET /api/v1/books/suggestions/?limit=10&q=h HTTP/1.1" 200 1596
INFO 2025-05-23 23:23:10,114 basehttp 2624 13516 "GET /api/v1/books/suggestions/?limit=10&q=p HTTP/1.1" 200 1580
INFO 2025-05-23 23:23:23,816 basehttp 2624 13516 "GET /api/v1/books/suggestions/?q=p HTTP/1.1" 200 664
INFO 2025-05-23 23:30:45,994 basehttp 2624 25044 "GET /api/v1/books/suggestions/?q=%22%20%22&author=JK HTTP/1.1" 200 44
INFO 2025-05-23 23:31:10,673 basehttp 2624 25044 "GET /api/v1/books/search/?q=%22%20%22&author=JK HTTP/1.1" 200 9255
INFO 2025-05-23 23:31:59,832 basehttp 2624 25044 "GET /api/v1/books/search/?author=JK&q=%22%22 HTTP/1.1" 200 9254
INFO 2025-05-23 23:38:50,712 autoreload 2624 16664 C:\Users\moata\Desktop\BookNestV2\BookNest\books\utils\book_service.py changed, reloading.
INFO 2025-05-23 23:38:52,876 autoreload 24728 21440 Watching for file changes with StatReloader
INFO 2025-05-23 23:39:07,794 basehttp 24728 21876 "GET /api/v1/books/search/?author=JK&q=%22%22 HTTP/1.1" 200 9254
INFO 2025-05-23 23:39:37,429 basehttp 24728 21876 "GET /api/v1/books/search/?q=o HTTP/1.1" 200 2807
INFO 2025-05-23 23:39:55,711 basehttp 24728 21876 "GET /api/v1/books/search/?q=x HTTP/1.1" 200 7527
INFO 2025-05-23 23:40:13,784 basehttp 24728 21876 "GET /api/v1/books/search/?q=marvel HTTP/1.1" 200 10152
INFO 2025-05-23 23:59:03,394 basehttp 24728 24612 "GET /api/v1/books/search/?q=iron HTTP/1.1" 200 7530
INFO 2025-05-23 23:59:27,776 basehttp 24728 24612 "GET /api/v1/books/search/?q=iron%20man HTTP/1.1" 200 7534
INFO 2025-05-23 23:59:37,543 basehttp 24728 24612 "GET /api/v1/books/search/?q=stan%20lee HTTP/1.1" 200 7534
INFO 2025-05-24 00:00:36,643 basehttp 24728 24612 "GET /api/v1/books/search/?q=beasts HTTP/1.1" 200 9782
WARNING 2025-05-24 00:02:29,638 log 24728 14040 Unauthorized: /api/v1/books/search/
WARNING 2025-05-24 00:02:29,639 basehttp 24728 14040 "GET /api/v1/books/search/?q=J.%20K.%20Rowling HTTP/1.1" 401 172
INFO 2025-05-24 00:02:35,130 basehttp 24728 14040 "POST /api/v1/users/token/refresh/ HTTP/1.1" 200 334
INFO 2025-05-24 00:02:39,940 basehttp 24728 14040 "GET /api/v1/books/search/?q=J.%20K.%20Rowling HTTP/1.1" 200 2831
INFO 2025-05-24 00:03:06,891 basehttp 24728 14040 "GET /api/v1/books/search/?author=&q=J.%20K.%20Rowling HTTP/1.1" 200 2831
INFO 2025-05-24 00:03:40,059 basehttp 24728 14040 "GET /api/v1/books/search/?q=J.%20K.%20Rowling&author=J.%20K.%20Rowling HTTP/1.1" 200 6550
INFO 2025-05-24 00:20:31,416 autoreload 24728 21440 C:\Users\moata\Desktop\BookNestV2\BookNest\books\views\search_views.py changed, reloading.
INFO 2025-05-24 00:20:35,693 autoreload 25336 23544 Watching for file changes with StatReloader
INFO 2025-05-24 00:22:23,742 autoreload 25336 23544 C:\Users\moata\Desktop\BookNestV2\BookNest\books\views\suggestion_views.py changed, reloading.
INFO 2025-05-24 00:22:27,021 autoreload 22844 11784 Watching for file changes with StatReloader
INFO 2025-05-24 00:31:20,657 basehttp 22844 20588 "GET /api/v1/books/search/?q=J.%20K.%20Rowling&author=J.%20K.%20Rowling HTTP/1.1" 200 6655
INFO 2025-05-24 00:33:22,161 basehttp 22844 22520 "GET /api/v1/books/search/?q=Stan%20Lee&author=Stan%20Lee HTTP/1.1" 200 11587
INFO 2025-05-24 00:35:45,395 basehttp 22844 16472 "GET /api/v1/books/search/?q=ant%20man HTTP/1.1" 200 12287
INFO 2025-05-24 00:39:25,282 basehttp 22844 20360 "GET /api/v1/books/search/?q=black%20panter HTTP/1.1" 200 12419
INFO 2025-05-24 00:42:54,721 basehttp 22844 20652 "GET /api/v1/books/search/?q=%22%20%22 HTTP/1.1" 200 9377
INFO 2025-05-24 00:46:34,689 basehttp 22844 24432 "GET /api/v1/books/search/?q=%22java%22 HTTP/1.1" 200 7134
INFO 2025-05-24 00:53:23,516 basehttp 22844 22832 "GET /api/v1/books/search/?q=java&page_size=40 HTTP/1.1" 200 17358
INFO 2025-05-24 01:27:42,120 autoreload 22844 11784 C:\Users\moata\Desktop\BookNestV2\BookNest\books\models.py changed, reloading.
INFO 2025-05-24 01:27:45,005 autoreload 2224 5604 Watching for file changes with StatReloader
INFO 2025-05-24 01:28:57,029 autoreload 2224 5604 C:\Users\moata\Desktop\BookNestV2\BookNest\books\models.py changed, reloading.
INFO 2025-05-24 01:28:59,210 autoreload 22712 11016 Watching for file changes with StatReloader
INFO 2025-05-24 01:29:14,270 autoreload 22712 11016 C:\Users\moata\Desktop\BookNestV2\BookNest\books\models.py changed, reloading.
INFO 2025-05-24 01:29:16,789 autoreload 18800 6540 Watching for file changes with StatReloader
INFO 2025-05-24 01:29:37,392 autoreload 18800 6540 C:\Users\moata\Desktop\BookNestV2\BookNest\books\utils\book_normalizer.py changed, reloading.
INFO 2025-05-24 01:29:39,672 autoreload 19088 24560 Watching for file changes with StatReloader
INFO 2025-05-24 01:30:12,238 autoreload 19088 24560 C:\Users\moata\Desktop\BookNestV2\BookNest\books\utils\book_normalizer.py changed, reloading.
INFO 2025-05-24 01:30:15,531 autoreload 21532 14944 Watching for file changes with StatReloader
INFO 2025-05-24 01:33:39,227 autoreload 21532 14944 C:\Users\moata\Desktop\BookNestV2\BookNest\books\utils\book_service.py changed, reloading.
INFO 2025-05-24 01:33:42,036 autoreload 2424 17888 Watching for file changes with StatReloader
INFO 2025-05-24 01:33:59,522 autoreload 2424 17888 C:\Users\moata\Desktop\BookNestV2\BookNest\books\utils\book_service.py changed, reloading.
INFO 2025-05-24 01:34:02,814 autoreload 23588 24572 Watching for file changes with StatReloader
INFO 2025-05-24 01:34:37,231 autoreload 23588 24572 C:\Users\moata\Desktop\BookNestV2\BookNest\books\models.py changed, reloading.
INFO 2025-05-24 01:34:40,188 autoreload 23268 18940 Watching for file changes with StatReloader
INFO 2025-05-24 01:41:10,450 autoreload 23268 18940 C:\Users\moata\Desktop\BookNestV2\BookNest\books\utils\book_service.py changed, reloading.
INFO 2025-05-24 01:41:13,114 autoreload 4688 20360 Watching for file changes with StatReloader
WARNING 2025-05-24 01:41:26,779 log 4688 11620 Unauthorized: /api/v1/books/search/
WARNING 2025-05-24 01:41:26,779 basehttp 4688 11620 "GET /api/v1/books/search/?q=java&page_size=40 HTTP/1.1" 401 172
INFO 2025-05-24 01:41:32,056 basehttp 4688 11620 "POST /api/v1/users/token/refresh/ HTTP/1.1" 200 334
INFO 2025-05-24 01:43:02,842 autoreload 22660 13496 Watching for file changes with StatReloader
INFO 2025-05-24 01:43:30,991 basehttp 22660 6748 "GET /api/v1/books/search/?q=java&page_size=40 HTTP/1.1" 200 18038
INFO 2025-05-24 01:44:35,285 basehttp 22660 11972 "GET /api/v1/books/search/?page_size=40&q=harry HTTP/1.1" 200 31280
INFO 2025-05-24 01:46:59,603 basehttp 22660 10684 "GET /api/v1/books/authors/ HTTP/1.1" 200 10233
INFO 2025-05-24 01:47:46,194 basehttp 22660 10684 "GET /api/v1/books/authors/1/ HTTP/1.1" 200 139
INFO 2025-05-24 02:09:41,474 autoreload 5612 9980 Watching for file changes with StatReloader
INFO 2025-05-24 02:09:47,034 basehttp 5612 9180 "GET /api/v1/books/authors/1/ HTTP/1.1" 200 139
INFO 2025-05-24 02:11:02,172 basehttp 5612 17464 "GET /api/v1/books/authors/ HTTP/1.1" 200 10233
INFO 2025-05-24 02:12:48,903 basehttp 5612 9000 "GET /api/v1/books/search/?q=harry HTTP/1.1" 200 9656
INFO 2025-05-24 02:14:06,751 basehttp 5612 9092 "GET /api/v1/books/authors/2 HTTP/1.1" 301 0
INFO 2025-05-24 02:14:06,838 basehttp 5612 25292 "GET /api/v1/books/authors/2/ HTTP/1.1" 200 141
INFO 2025-05-26 13:25:16,300 autoreload 24072 20788 Watching for file changes with StatReloader
INFO 2025-05-26 14:25:12,723 autoreload 17940 8308 Watching for file changes with StatReloader
WARNING 2025-05-26 14:33:22,522 log 17940 7096 Unauthorized: /api/v1/users/login/
WARNING 2025-05-26 14:33:22,528 basehttp 17940 7096 "POST /api/v1/users/login/ HTTP/1.1" 401 172
INFO 2025-05-26 14:33:28,649 basehttp 17940 7096 "POST /api/v1/users/token/refresh/ HTTP/1.1" 200 334
INFO 2025-05-26 14:33:35,274 basehttp 17940 7096 "POST /api/v1/users/login/ HTTP/1.1" 200 659
INFO 2025-05-26 14:33:48,169 basehttp 17940 7096 "GET /api/v1/books/books/9780747532743/reviews/ HTTP/1.1" 200 712
WARNING 2025-05-26 14:37:23,747 log 17940 15236 Not Found: /
WARNING 2025-05-26 14:37:23,750 basehttp 17940 15236 "GET / HTTP/1.1" 404 3624
WARNING 2025-05-26 14:37:24,200 log 17940 15236 Not Found: /favicon.ico
WARNING 2025-05-26 14:37:24,201 basehttp 17940 15236 "GET /favicon.ico HTTP/1.1" 404 3675
INFO 2025-05-26 14:37:29,026 basehttp 17940 15236 "GET /admin HTTP/1.1" 301 0
INFO 2025-05-26 14:37:29,109 basehttp 17940 14436 "GET /admin/ HTTP/1.1" 302 0
INFO 2025-05-26 14:37:29,297 basehttp 17940 14436 "GET /admin/login/?next=/admin/ HTTP/1.1" 200 4160
INFO 2025-05-26 14:37:30,028 basehttp 17940 4932 "GET /static/admin/css/nav_sidebar.css HTTP/1.1" 200 2810
INFO 2025-05-26 14:37:30,038 basehttp 17940 14504 "GET /static/admin/js/theme.js HTTP/1.1" 200 1653
INFO 2025-05-26 14:37:30,053 basehttp 17940 26712 "GET /static/admin/css/dark_mode.css HTTP/1.1" 200 2804
INFO 2025-05-26 14:37:30,061 basehttp 17940 14436 "GET /static/admin/css/base.css HTTP/1.1" 200 22092
INFO 2025-05-26 14:37:30,065 basehttp 17940 4932 "GET /static/admin/css/responsive.css HTTP/1.1" 200 17972
INFO 2025-05-26 14:37:30,066 basehttp 17940 14596 "GET /static/admin/css/login.css HTTP/1.1" 200 951
INFO 2025-05-26 14:37:30,067 basehttp 17940 2960 "GET /static/admin/js/nav_sidebar.js HTTP/1.1" 200 3063
INFO 2025-05-26 14:37:38,317 basehttp 17940 14436 "POST /admin/login/?next=/admin/ HTTP/1.1" 302 0
INFO 2025-05-26 14:37:38,332 basehttp 17940 14436 "GET /admin/ HTTP/1.1" 302 0
INFO 2025-05-26 14:37:38,354 basehttp 17940 14436 "GET /admin/login/?next=/admin/ HTTP/1.1" 200 4160
INFO 2025-05-26 14:37:49,391 basehttp 17940 14436 "POST /admin/login/?next=/admin/ HTTP/1.1" 200 4322
INFO 2025-05-26 14:39:01,250 autoreload 11100 15208 Watching for file changes with StatReloader
INFO 2025-05-26 14:39:11,435 basehttp 11100 23648 "POST /admin/login/?next=/admin/ HTTP/1.1" 302 0
INFO 2025-05-26 14:39:11,597 basehttp 11100 23648 "GET /admin/ HTTP/1.1" 302 0
INFO 2025-05-26 14:39:11,753 basehttp 11100 23648 "GET /admin/login/?next=/admin/ HTTP/1.1" 200 4160
INFO 2025-05-26 14:39:20,448 basehttp 11100 23648 "POST /admin/login/?next=/admin/ HTTP/1.1" 302 0
INFO 2025-05-26 14:39:20,462 basehttp 11100 23648 "GET /admin/ HTTP/1.1" 302 0
INFO 2025-05-26 14:39:20,480 basehttp 11100 23648 "GET /admin/login/?next=/admin/ HTTP/1.1" 200 4160
INFO 2025-05-26 14:39:26,655 basehttp 11100 23648 "GET /admin/login/?next=/admin/ HTTP/1.1" 200 4160
INFO 2025-05-26 14:39:34,894 basehttp 11100 23648 "POST /admin/login/?next=/admin/ HTTP/1.1" 302 0
INFO 2025-05-26 14:39:34,914 basehttp 11100 23648 "GET /admin/ HTTP/1.1" 302 0
INFO 2025-05-26 14:39:34,941 basehttp 11100 23648 "GET /admin/login/?next=/admin/ HTTP/1.1" 200 4160
WARNING 2025-05-26 14:40:05,579 log 11100 23044 Not Found: /
WARNING 2025-05-26 14:40:05,585 basehttp 11100 23044 "GET /?ide_webview_request_time=1748259605037 HTTP/1.1" 404 3663
INFO 2025-05-26 14:40:10,931 basehttp 11100 23044 "GET /admin?ide_webview_request_time=1748259610907 HTTP/1.1" 301 0
INFO 2025-05-26 14:40:10,942 basehttp 11100 23268 "GET /admin/?ide_webview_request_time=1748259610907 HTTP/1.1" 302 0
INFO 2025-05-26 14:40:10,973 basehttp 11100 23268 "GET /admin/login/?next=/admin/%3Fide_webview_request_time%3D1748259610907 HTTP/1.1" 200 4242
INFO 2025-05-26 14:40:11,117 basehttp 11100 23268 "GET /static/admin/css/base.css HTTP/1.1" 200 22092
INFO 2025-05-26 14:40:11,118 basehttp 11100 23268 "GET /static/admin/css/dark_mode.css HTTP/1.1" 200 2804
INFO 2025-05-26 14:40:11,122 basehttp 11100 23268 "GET /static/admin/css/nav_sidebar.css HTTP/1.1" 200 2810
INFO 2025-05-26 14:40:11,125 basehttp 11100 23268 "GET /static/admin/css/login.css HTTP/1.1" 200 951
INFO 2025-05-26 14:40:11,128 basehttp 11100 23268 "GET /static/admin/css/responsive.css HTTP/1.1" 200 17972
INFO 2025-05-26 14:40:11,132 basehttp 11100 23268 "GET /static/admin/js/theme.js HTTP/1.1" 200 1653
INFO 2025-05-26 14:40:11,136 basehttp 11100 23268 "GET /static/admin/js/nav_sidebar.js HTTP/1.1" 200 3063
WARNING 2025-05-26 14:40:16,254 log 11100 23268 Forbidden (CSRF cookie not set.): /admin/login/
WARNING 2025-05-26 14:40:16,256 basehttp 11100 23268 "POST /admin/login/?next=/admin/%3Fide_webview_request_time%3D1748259610907 HTTP/1.1" 403 2855
INFO 2025-05-26 14:41:05,486 basehttp 11100 6356 "GET /api/v1/books/books/9780747532743/reviews/ HTTP/1.1" 200 712
WARNING 2025-05-26 14:45:28,836 log 11100 22292 Method Not Allowed: /api/v1/books/reviews/4/vote/
WARNING 2025-05-26 14:45:28,838 basehttp 11100 22292 "GET /api/v1/books/reviews/4/vote/ HTTP/1.1" 405 40
INFO 2025-05-26 14:46:35,546 basehttp 11100 23644 "POST /api/v1/books/reviews/4/vote/ HTTP/1.1" 201 114
INFO 2025-05-26 14:46:51,270 basehttp 11100 23644 "GET /api/v1/books/books/9780747532743/reviews/ HTTP/1.1" 200 715
WARNING 2025-05-26 14:47:57,243 log 11100 23408 Method Not Allowed: /api/v1/books/reviews/4/vote/
WARNING 2025-05-26 14:47:57,245 basehttp 11100 23408 "GET /api/v1/books/reviews/4/vote/ HTTP/1.1" 405 40
INFO 2025-05-26 14:48:02,191 basehttp 11100 23408 "POST /api/v1/books/reviews/4/vote/ HTTP/1.1" 200 114
INFO 2025-05-26 14:48:25,642 basehttp 11100 23408 "POST /api/v1/books/reviews/4/vote/ HTTP/1.1" 200 109
INFO 2025-05-26 14:48:37,004 basehttp 11100 23408 "POST /api/v1/books/reviews/4/vote/ HTTP/1.1" 200 114
WARNING 2025-05-26 14:48:53,391 log 11100 23408 Method Not Allowed: /api/v1/books/books/9780747532743/reviews/
WARNING 2025-05-26 14:48:53,392 basehttp 11100 23408 "POST /api/v1/books/books/9780747532743/reviews/ HTTP/1.1" 405 41
INFO 2025-05-26 14:48:58,453 basehttp 11100 23408 "GET /api/v1/books/books/9780747532743/reviews/ HTTP/1.1" 200 718
INFO 2025-05-26 14:50:14,295 basehttp 11100 18060 "POST /api/v1/books/reviews/1/vote/ HTTP/1.1" 201 114
WARNING 2025-05-26 14:50:22,645 log 11100 18060 Method Not Allowed: /api/v1/books/books/9780747532743/reviews/
WARNING 2025-05-26 14:50:22,648 basehttp 11100 18060 "POST /api/v1/books/books/9780747532743/reviews/ HTTP/1.1" 405 41
INFO 2025-05-26 14:50:27,511 basehttp 11100 18060 "GET /api/v1/books/books/9780747532743/reviews/ HTTP/1.1" 200 721
WARNING 2025-05-26 14:51:11,787 log 11100 18060 Not Found: /api/v1/books/reviews/user-voted/
WARNING 2025-05-26 14:51:11,789 basehttp 11100 18060 "GET /api/v1/books/reviews/user-voted/ HTTP/1.1" 404 23
WARNING 2025-05-26 14:52:33,220 log 11100 8008 Method Not Allowed: /api/v1/books/reviews/1/vote/
WARNING 2025-05-26 14:52:33,221 basehttp 11100 8008 "DELETE /api/v1/books/reviews/1/vote/ HTTP/1.1" 405 43
INFO 2025-05-26 14:56:08,141 basehttp 11100 20760 "DELETE /api/v1/books/reviews/1/vote/remove/ HTTP/1.1" 200 93
INFO 2025-05-26 14:56:22,529 basehttp 11100 20760 "GET /api/v1/books/books/9780747532743/reviews/ HTTP/1.1" 200 718
INFO 2025-05-26 14:56:44,600 autoreload 11100 15208 C:\Users\moata\Desktop\BookNestV2\BookNest\books\views\vote_views.py changed, reloading.
INFO 2025-05-26 14:56:47,203 autoreload 13368 9832 Watching for file changes with StatReloader
WARNING 2025-05-26 14:58:03,689 log 13368 3544 Not Found: /api/v1/books/books/reviews/vote/
WARNING 2025-05-26 14:58:03,691 basehttp 13368 3544 "GET /api/v1/books/books/reviews/vote/ HTTP/1.1" 404 17981
WARNING 2025-05-26 14:58:10,106 log 13368 3544 Not Found: /api/v1/books/books/reviews/1/vote/
WARNING 2025-05-26 14:58:10,107 basehttp 13368 3544 "GET /api/v1/books/books/reviews/1/vote/ HTTP/1.1" 404 17987
WARNING 2025-05-26 14:58:16,165 log 13368 3544 Not Found: /api/v1/books/books/reviews/1/vote/
WARNING 2025-05-26 14:58:16,168 basehttp 13368 3544 "POST /api/v1/books/books/reviews/1/vote/ HTTP/1.1" 404 17988
WARNING 2025-05-26 14:58:33,413 log 13368 3544 Not Found: /api/v1/books/books/reviews/1/vote
WARNING 2025-05-26 14:58:33,414 basehttp 13368 3544 "POST /api/v1/books/books/reviews/1/vote HTTP/1.1" 404 17985
INFO 2025-05-26 14:58:49,687 basehttp 13368 3544 "POST /api/v1/books/reviews/1/vote/ HTTP/1.1" 201 114
WARNING 2025-05-26 14:58:57,307 log 13368 3544 Not Found: /api/v1/books/book
WARNING 2025-05-26 14:58:57,310 basehttp 13368 3544 "POST /api/v1/books/book HTTP/1.1" 404 17937
INFO 2025-05-26 14:59:01,995 basehttp 13368 3544 "GET /api/v1/books/books/9780747532743/reviews/ HTTP/1.1" 200 721
INFO 2025-05-26 14:59:41,027 basehttp 13368 3544 "GET /api/v1/books/reviews/1/vote/status/ HTTP/1.1" 200 134
INFO 2025-05-26 15:00:00,046 basehttp 13368 3544 "GET /api/v1/books/reviews/1/vote/stats/ HTTP/1.1" 200 183
WARNING 2025-05-26 15:02:20,333 log 13368 9504 Not Found: /api/v1/books/reviews/user-voted/
WARNING 2025-05-26 15:02:20,335 basehttp 13368 9504 "GET /api/v1/books/reviews/user-voted/ HTTP/1.1" 404 23
INFO 2025-05-26 15:03:43,778 autoreload 13368 9832 C:\Users\moata\Desktop\BookNestV2\BookNest\books\views\vote_views.py changed, reloading.
INFO 2025-05-26 15:03:46,065 autoreload 2328 3608 Watching for file changes with StatReloader
INFO 2025-05-26 15:03:58,564 basehttp 2328 27412 "GET /api/v1/books/reviews/user/voted/ HTTP/1.1" 200 721
WARNING 2025-05-26 15:04:21,595 log 2328 27412 Not Found: /api/v1/books/reviews/by-votes/
WARNING 2025-05-26 15:04:21,596 basehttp 2328 27412 "GET /api/v1/books/reviews/by-votes/ HTTP/1.1" 404 23
INFO 2025-05-26 15:05:04,789 basehttp 2328 27412 "GET /api/v1/books/reviews/user/voted/ HTTP/1.1" 200 721
INFO 2025-05-26 15:05:35,584 basehttp 2328 27412 "GET /api/v1/books/reviews/user/voted?vote-type=upvote HTTP/1.1" 301 0
INFO 2025-05-26 15:05:35,694 basehttp 2328 16600 "GET /api/v1/books/reviews/user/voted/?vote-type=upvote HTTP/1.1" 200 721
INFO 2025-05-26 15:05:48,596 basehttp 2328 16600 "GET /api/v1/books/reviews/user/voted?vote-type=downvote HTTP/1.1" 301 0
INFO 2025-05-26 15:05:48,702 basehttp 2328 5372 "GET /api/v1/books/reviews/user/voted/?vote-type=downvote HTTP/1.1" 200 721
INFO 2025-05-26 15:08:08,048 basehttp 2328 7856 "GET /api/v1/books/reviews/by-votes HTTP/1.1" 301 0
WARNING 2025-05-26 15:08:08,182 log 2328 8628 Not Found: /api/v1/books/reviews/by-votes/
WARNING 2025-05-26 15:08:08,184 basehttp 2328 8628 "GET /api/v1/books/reviews/by-votes/ HTTP/1.1" 404 23
WARNING 2025-05-26 15:12:40,868 log 2328 22560 Not Found: /api/v1/books/reviews/by-votes/
WARNING 2025-05-26 15:12:40,869 basehttp 2328 22560 "GET /api/v1/books/reviews/by-votes/ HTTP/1.1" 404 23
INFO 2025-05-26 15:13:37,782 autoreload 2328 3608 C:\Users\moata\Desktop\BookNestV2\BookNest\books\urls.py changed, reloading.
INFO 2025-05-26 15:13:40,496 autoreload 4976 15084 Watching for file changes with StatReloader
WARNING 2025-05-26 15:13:54,948 log 4976 25460 Not Found: /api/v1/books/reviews/by-votes/
WARNING 2025-05-26 15:13:54,949 basehttp 4976 25460 "GET /api/v1/books/reviews/by-votes/ HTTP/1.1" 404 23
INFO 2025-05-26 15:14:18,920 autoreload 4976 15084 C:\Users\moata\Desktop\BookNestV2\BookNest\books\urls.py changed, reloading.
INFO 2025-05-26 15:14:21,297 autoreload 21360 15996 Watching for file changes with StatReloader
INFO 2025-05-26 15:14:27,868 basehttp 21360 21856 "GET /api/v1/books/reviewss/by-votes/ HTTP/1.1" 200 1097
INFO 2025-05-26 15:15:21,110 basehttp 21360 21856 "GET /api/v1/books/reviewss/by-votes/ HTTP/1.1" 200 1097
INFO 2025-05-26 15:15:53,401 basehttp 21360 21856 "GET /api/v1/books/reviewss/by-votes/?book_id=9780553103540 HTTP/1.1" 200 377
INFO 2025-05-26 15:16:01,560 basehttp 21360 21856 "GET /api/v1/books/reviewss/by-votes/ HTTP/1.1" 200 1097
INFO 2025-05-26 15:16:17,092 basehttp 21360 21856 "GET /api/v1/books/reviewss/by-votes/?order=asc HTTP/1.1" 200 1097
INFO 2025-05-26 15:16:31,803 basehttp 21360 21856 "GET /api/v1/books/reviewss/by-votes/?order=desc HTTP/1.1" 200 1097
INFO 2025-05-26 15:17:18,202 autoreload 21360 15996 C:\Users\moata\Desktop\BookNestV2\BookNest\books\urls.py changed, reloading.
INFO 2025-05-26 15:17:21,237 autoreload 7280 11140 Watching for file changes with StatReloader
WARNING 2025-05-26 15:17:36,064 log 7280 16900 Not Found: /api/v1/books/reviewss/by-votes/
WARNING 2025-05-26 15:17:36,065 basehttp 7280 16900 "GET /api/v1/books/reviewss/by-votes/?order=desc HTTP/1.1" 404 17989
WARNING 2025-05-26 15:17:45,161 log 7280 16900 Not Found: /api/v1/books/reviews/by-votes/
WARNING 2025-05-26 15:17:45,162 basehttp 7280 16900 "GET /api/v1/books/reviews/by-votes/ HTTP/1.1" 404 23
INFO 2025-05-26 15:18:01,195 autoreload 7280 11140 C:\Users\moata\Desktop\BookNestV2\BookNest\books\urls.py changed, reloading.
INFO 2025-05-26 15:18:03,795 autoreload 25812 22300 Watching for file changes with StatReloader
WARNING 2025-05-26 15:18:07,317 log 25812 14972 Not Found: /api/v1/books/reviews/by-votes/
WARNING 2025-05-26 15:18:07,319 basehttp 25812 14972 "GET /api/v1/books/reviews/by-votes/ HTTP/1.1" 404 23
INFO 2025-05-26 15:18:14,059 basehttp 25812 14972 "GET /api/v1/books/review/by-votes/ HTTP/1.1" 200 1097
WARNING 2025-05-26 15:19:55,520 log 25812 17256 Not Found: /api/v1/books/review/2/toggle/
WARNING 2025-05-26 15:19:55,523 basehttp 25812 17256 "GET /api/v1/books/review/2/toggle/ HTTP/1.1" 404 17971
WARNING 2025-05-26 15:20:02,053 log 25812 17256 Not Found: /api/v1/books/reviews/2/toggle/
WARNING 2025-05-26 15:20:02,057 basehttp 25812 17256 "GET /api/v1/books/reviews/2/toggle/ HTTP/1.1" 404 17974
WARNING 2025-05-26 15:20:07,094 log 25812 17256 Not Found: /api/v1/books/reviews/2/toggle/
WARNING 2025-05-26 15:20:07,095 basehttp 25812 17256 "POST /api/v1/books/reviews/2/toggle/ HTTP/1.1" 404 17975
WARNING 2025-05-26 15:20:25,378 log 25812 17256 Not Found: /api/v1/books/reviews/vote/2/toggle/
WARNING 2025-05-26 15:20:25,379 basehttp 25812 17256 "POST /api/v1/books/reviews/vote/2/toggle/ HTTP/1.1" 404 17990
INFO 2025-05-26 15:20:34,698 basehttp 25812 17256 "POST /api/v1/books/reviews/2/vote/toggle/ HTTP/1.1" 201 119
INFO 2025-05-26 15:20:47,216 basehttp 25812 17256 "POST /api/v1/books/reviews/2/vote/toggle/ HTTP/1.1" 200 109
INFO 2025-05-26 15:20:49,517 basehttp 25812 17256 "POST /api/v1/books/reviews/2/vote/toggle/ HTTP/1.1" 200 97
INFO 2025-05-26 15:20:54,427 basehttp 25812 17256 "POST /api/v1/books/reviews/2/vote/toggle/ HTTP/1.1" 201 114
INFO 2025-05-26 15:20:58,189 basehttp 25812 17256 "POST /api/v1/books/reviews/2/vote/toggle/ HTTP/1.1" 200 97
INFO 2025-05-26 15:21:00,320 basehttp 25812 17256 "POST /api/v1/books/reviews/2/vote/toggle/ HTTP/1.1" 201 114
INFO 2025-05-26 15:23:15,689 autoreload 25812 22300 C:\Users\moata\Desktop\BookNestV2\BookNest\BookNest\urls.py changed, reloading.
INFO 2025-05-26 15:23:18,004 autoreload 22404 13008 Watching for file changes with StatReloader
